Workbook

Sheet مرتبات2
A1: ديسمبر 2025
B2: الشهر | D2: 45870
A3: م | B3: الاسماء / Name | C3: - | D3: صافي الاتعاب والمرتبات / Salary | E3: إضافات غير مباشرة / In direct additions | F3: إضافات مباشرة / Direct Additions | G3: زيادة سنوية / Yearly Increase | H3: علاوات / Bouns | I3: خصومات / Deductions | J3: الإجمالي قبل الخصم GROSS | K3: الصافى بعد الخصم أو الزيادة NET | M3: طريقة الدفع | N3: رقم الحساب | O3: ملحوظات | P3: تحويل/شيك
A4: 1 | B4: د/هانى صلاح الدين محمد سري الدين | D4: 0 | E4: =HYPERLINK(اضافات!N4) -> 0 | F4: =HYPERLINK(اضافات!M4) -> 0 | G4: =HYPERLINK(اضافات!F4) -> 0 | H4: =HYPERLINK(اضافات!O4) -> 0 | I4: =HYPERLINK(خصومات!L4) -> 0 | J4: =SUM(D4,VALUE(E4),VALUE(F4),VALUE(G4)) -> 0 | K4: =VALUE(D4)+VALUE(G4)+VALUE(H4)-VALUE(I4) -> 0
A5: 2 | B5: أ/أميرة محمد على شريف | D5: 0 | E5: =HYPERLINK(اضافات!N5) -> 0 | F5: =HYPERLINK(اضافات!M5) -> 0 | G5: =HYPERLINK(اضافات!F5) -> 0 | H5: =HYPERLINK(اضافات!O5) -> 0 | I5: =HYPERLINK(خصومات!L5) -> 0 | J5: =SUM(D5,VALUE(E5),VALUE(F5),VALUE(G5)) -> 0 | K5: =VALUE(D5)+VALUE(G5)+VALUE(H5)-VALUE(I5) -> 0
A6: 3 | B6: أ/إيهاب حمدى ابراهيم | D6: 0 | E6: =HYPERLINK(اضافات!N6) -> 0 | F6: =HYPERLINK(اضافات!M6) -> 0 | G6: =HYPERLINK(اضافات!F6) -> 0 | H6: =HYPERLINK(اضافات!O6) -> 0 | I6: =HYPERLINK(خصومات!L6) -> 0 | J6: =SUM(D6,VALUE(E6),VALUE(F6),VALUE(G6)) -> 0 | K6: =VALUE(D6)+VALUE(G6)+VALUE(H6)-VALUE(I6) -> 0
B7: Spare | D7: 0 | E7: =HYPERLINK(اضافات!N7) -> 0 | F7: =HYPERLINK(اضافات!M7) -> 0 | G7: =HYPERLINK(اضافات!F7) -> 0 | H7: =HYPERLINK(اضافات!O7) -> 0 | I7: =HYPERLINK(خصومات!L7) -> 0 | J7: =SUM(D7,VALUE(E7),VALUE(F7),VALUE(G7)) -> 0 | K7: =VALUE(D7)+VALUE(G7)+VALUE(H7)-VALUE(I7) -> 0
B8: Spare | D8: 0 | E8: =HYPERLINK(اضافات!N8) -> 0 | F8: =HYPERLINK(اضافات!M8) -> 0 | G8: =HYPERLINK(اضافات!F8) -> 0 | H8: =HYPERLINK(اضافات!O8) -> 0 | I8: =HYPERLINK(خصومات!L8) -> 0 | J8: =SUM(D8,VALUE(E8),VALUE(F8),VALUE(G8)) -> 0 | K8: =VALUE(D8)+VALUE(G8)+VALUE(H8)-VALUE(I8) -> 0
B9: Spare | D9: 0 | E9: =HYPERLINK(اضافات!N9) -> 0 | F9: =HYPERLINK(اضافات!M9) -> 0 | G9: =HYPERLINK(اضافات!F9) -> 0 | H9: =HYPERLINK(اضافات!O9) -> 0 | I9: =HYPERLINK(خصومات!L9) -> 0 | J9: =SUM(D9,VALUE(E9),VALUE(F9),VALUE(G9)) -> 0 | K9: =VALUE(D9)+VALUE(G9)+VALUE(H9)-VALUE(I9) -> 0
B10: Spare | D10: 0 | E10: =HYPERLINK(اضافات!N10) -> 0 | F10: =HYPERLINK(اضافات!M10) -> 0 | G10: =HYPERLINK(اضافات!F10) -> 0 | H10: =HYPERLINK(اضافات!O10) -> 0 | I10: =HYPERLINK(خصومات!L10) -> 0 | J10: =SUM(D10,VALUE(E10),VALUE(F10),VALUE(G10)) -> 0 | K10: =VALUE(D10)+VALUE(G10)+VALUE(H10)-VALUE(I10) -> 0
B11: Spare | D11: 0 | E11: =HYPERLINK(اضافات!N11) -> 0 | F11: =HYPERLINK(اضافات!M11) -> 0 | G11: =HYPERLINK(اضافات!F11) -> 0 | H11: =HYPERLINK(اضافات!O11) -> 0 | I11: =HYPERLINK(خصومات!L11) -> 0 | J11: =SUM(D11,VALUE(E11),VALUE(F11),VALUE(G11)) -> 0 | K11: =VALUE(D11)+VALUE(G11)+VALUE(H11)-VALUE(I11) -> 0
B12: Spare | D12: 0 | E12: =HYPERLINK(اضافات!N12) -> 0 | F12: =HYPERLINK(اضافات!M12) -> 0 | G12: =HYPERLINK(اضافات!F12) -> 0 | H12: =HYPERLINK(اضافات!O12) -> 0 | I12: =HYPERLINK(خصومات!L12) -> 0 | J12: =SUM(D12,VALUE(E12),VALUE(F12),VALUE(G12)) -> 0 | K12: =VALUE(D12)+VALUE(G12)+VALUE(H12)-VALUE(I12) -> 0
B13: Spare | D13: 0 | E13: =HYPERLINK(اضافات!N13) -> 0 | F13: =HYPERLINK(اضافات!M13) -> 0 | G13: =HYPERLINK(اضافات!F13) -> 0 | H13: =HYPERLINK(اضافات!O13) -> 0 | I13: =HYPERLINK(خصومات!L13) -> 0 | J13: =SUM(D13,VALUE(E13),VALUE(F13),VALUE(G13)) -> 0 | K13: =VALUE(D13)+VALUE(G13)+VALUE(H13)-VALUE(I13) -> 0
B14: Spare | D14: 0 | E14: =HYPERLINK(اضافات!N14) -> 0 | F14: =HYPERLINK(اضافات!M14) -> 0 | G14: =HYPERLINK(اضافات!F14) -> 0 | H14: =HYPERLINK(اضافات!O14) -> 0 | I14: =HYPERLINK(خصومات!L14) -> 0 | J14: =SUM(D14,VALUE(E14),VALUE(F14),VALUE(G14)) -> 0 | K14: =VALUE(D14)+VALUE(G14)+VALUE(H14)-VALUE(I14) -> 0
B15: Spare | D15: 0 | E15: =HYPERLINK(اضافات!N15) -> 0 | F15: =HYPERLINK(اضافات!M15) -> 0 | G15: =HYPERLINK(اضافات!F15) -> 0 | H15: =HYPERLINK(اضافات!O15) -> 0 | I15: =HYPERLINK(خصومات!L15) -> 0 | J15: =SUM(D15,VALUE(E15),VALUE(F15),VALUE(G15)) -> 0 | K15: =VALUE(D15)+VALUE(G15)+VALUE(H15)-VALUE(I15) -> 0
B16: Spare | D16: 0 | E16: =HYPERLINK(اضافات!N16) -> 0 | F16: =HYPERLINK(اضافات!M16) -> 0 | G16: =HYPERLINK(اضافات!F16) -> 0 | H16: =HYPERLINK(اضافات!O16) -> 0 | I16: =HYPERLINK(خصومات!L16) -> 0 | J16: =SUM(D16,VALUE(E16),VALUE(F16),VALUE(G16)) -> 0 | K16: =VALUE(D16)+VALUE(G16)+VALUE(H16)-VALUE(I16) -> 0
B17: Spare | D17: 0 | E17: =HYPERLINK(اضافات!N17) -> 0 | F17: =HYPERLINK(اضافات!M17) -> 0 | G17: =HYPERLINK(اضافات!F17) -> 0 | H17: =HYPERLINK(اضافات!O17) -> 0 | I17: =HYPERLINK(خصومات!L17) -> 0 | J17: =SUM(D17,VALUE(E17),VALUE(F17),VALUE(G17)) -> 0 | K17: =VALUE(D17)+VALUE(G17)+VALUE(H17)-VALUE(I17) -> 0
A18: 3 | B18: اجمالي الشركاء | D18: =SUM(D4:D17) -> 0 | E18: =SUM(E4:E17) -> 0 | F18: =SUM(F4:F17) -> 0 | G18: =SUM(G4:G17) -> 0 | H18: =SUM(H4:H17) -> 0 | I18: =SUM(I4:I17) -> 0 | J18: =SUM(J4:J17) -> 0 | K18: =SUM(K4:K17) -> 0 | L18: =SUM(K4:K17) -> 0
A19: 1 | B19: أ/ناجى رمضان أمين محمد | D19: 0 | E19: =HYPERLINK(اضافات!N19) -> 0 | F19: =HYPERLINK(اضافات!M19) -> 0 | G19: =HYPERLINK(اضافات!F19) -> 0 | H19: =HYPERLINK(اضافات!O19) -> 0 | I19: =HYPERLINK(خصومات!L19) -> 0 | J19: =SUM(D19,VALUE(E19),VALUE(F19),VALUE(G19)) -> 0 | K19: =VALUE(D19)+VALUE(G19)+VALUE(H19)-VALUE(I19) -> 0
A20: 2 | B20: أ/محمد عبد العزيز عبدالحافظ | D20: 0 | E20: =HYPERLINK(اضافات!N20) -> 0 | F20: =HYPERLINK(اضافات!M20) -> 0 | G20: =HYPERLINK(اضافات!F20) -> 0 | H20: =HYPERLINK(اضافات!O20) -> 0 | I20: =HYPERLINK(خصومات!L20) -> 0 | J20: =SUM(D20,VALUE(E20),VALUE(F20),VALUE(G20)) -> 0 | K20: =VALUE(D20)+VALUE(G20)+VALUE(H20)-VALUE(I20) -> 0
A21: 3 | B21: أ/ أحمد سعيد أحمد محمد علي | D21: 0 | E21: =HYPERLINK(اضافات!N21) -> 0 | F21: =HYPERLINK(اضافات!M21) -> 0 | G21: =HYPERLINK(اضافات!F21) -> 0 | H21: =HYPERLINK(اضافات!O21) -> 0 | I21: =HYPERLINK(خصومات!L21) -> 0 | J21: =SUM(D21,VALUE(E21),VALUE(F21),VALUE(G21)) -> 0 | K21: =VALUE(D21)+VALUE(G21)+VALUE(H21)-VALUE(I21) -> 0
A22: 4 | B22: أ/منة الله البلتاجى | D22: 0 | E22: =HYPERLINK(اضافات!N22) -> 0 | F22: =HYPERLINK(اضافات!M22) -> 0 | G22: =HYPERLINK(اضافات!F22) -> 0 | H22: =HYPERLINK(اضافات!O22) -> 0 | I22: =HYPERLINK(خصومات!L22) -> 0 | J22: =SUM(D22,VALUE(E22),VALUE(F22),VALUE(G22)) -> 0 | K22: =VALUE(D22)+VALUE(G22)+VALUE(H22)-VALUE(I22) -> 0
A23: 5 | B23: أ/نهى عمرو محمد رضوان | D23: 0 | E23: =HYPERLINK(اضافات!N23) -> 0 | F23: =HYPERLINK(اضافات!M23) -> 0 | G23: =HYPERLINK(اضافات!F23) -> 0 | H23: =HYPERLINK(اضافات!O23) -> 0 | I23: =HYPERLINK(خصومات!L23) -> 0 | J23: =SUM(D23,VALUE(E23),VALUE(F23),VALUE(G23)) -> 0 | K23: =VALUE(D23)+VALUE(G23)+VALUE(H23)-VALUE(I23) -> 0
A24: 6 | B24: أ/عبد الله عمرو حافظ | D24: 0 | E24: =HYPERLINK(اضافات!N24) -> 0 | F24: =HYPERLINK(اضافات!M24) -> 0 | G24: =HYPERLINK(اضافات!F24) -> 0 | H24: =HYPERLINK(اضافات!O24) -> 0 | I24: =HYPERLINK(خصومات!L24) -> 0 | J24: =SUM(D24,VALUE(E24),VALUE(F24),VALUE(G24)) -> 0 | K24: =VALUE(D24)+VALUE(G24)+VALUE(H24)-VALUE(I24) -> 0
A25: 7 | B25: أ/محمد حمدى كامل | D25: 0 | E25: =HYPERLINK(اضافات!N25) -> 0 | F25: =HYPERLINK(اضافات!M25) -> 0 | G25: =HYPERLINK(اضافات!F25) -> 0 | H25: =HYPERLINK(اضافات!O25) -> 0 | I25: =HYPERLINK(خصومات!L25) -> 0 | J25: =SUM(D25,VALUE(E25),VALUE(F25),VALUE(G25)) -> 0 | K25: =VALUE(D25)+VALUE(G25)+VALUE(H25)-VALUE(I25) -> 0
B26: Spare | D26: 0 | E26: =HYPERLINK(اضافات!N26) -> 0 | F26: =HYPERLINK(اضافات!M26) -> 0 | G26: =HYPERLINK(اضافات!F26) -> 0 | H26: =HYPERLINK(اضافات!O26) -> 0 | I26: =HYPERLINK(خصومات!L26) -> 0 | J26: =SUM(D26,VALUE(E26),VALUE(F26),VALUE(G26)) -> 0 | K26: =VALUE(D26)+VALUE(G26)+VALUE(H26)-VALUE(I26) -> 0
B27: Spare | D27: 0 | E27: =HYPERLINK(اضافات!N27) -> 0 | F27: =HYPERLINK(اضافات!M27) -> 0 | G27: =HYPERLINK(اضافات!F27) -> 0 | H27: =HYPERLINK(اضافات!O27) -> 0 | I27: =HYPERLINK(خصومات!L27) -> 0 | J27: =SUM(D27,VALUE(E27),VALUE(F27),VALUE(G27)) -> 0 | K27: =VALUE(D27)+VALUE(G27)+VALUE(H27)-VALUE(I27) -> 0
B28: Spare | D28: 0 | E28: =HYPERLINK(اضافات!N28) -> 0 | F28: =HYPERLINK(اضافات!M28) -> 0 | G28: =HYPERLINK(اضافات!F28) -> 0 | H28: =HYPERLINK(اضافات!O28) -> 0 | I28: =HYPERLINK(خصومات!L28) -> 0 | J28: =SUM(D28,VALUE(E28),VALUE(F28),VALUE(G28)) -> 0 | K28: =VALUE(D28)+VALUE(G28)+VALUE(H28)-VALUE(I28) -> 0
B29: Spare | D29: 0 | E29: =HYPERLINK(اضافات!N29) -> 0 | F29: =HYPERLINK(اضافات!M29) -> 0 | G29: =HYPERLINK(اضافات!F29) -> 0 | H29: =HYPERLINK(اضافات!O29) -> 0 | I29: =HYPERLINK(خصومات!L29) -> 0 | J29: =SUM(D29,VALUE(E29),VALUE(F29),VALUE(G29)) -> 0 | K29: =VALUE(D29)+VALUE(G29)+VALUE(H29)-VALUE(I29) -> 0
B30: Spare | D30: 0 | E30: =HYPERLINK(اضافات!N30) -> 0 | F30: =HYPERLINK(اضافات!M30) -> 0 | G30: =HYPERLINK(اضافات!F30) -> 0 | H30: =HYPERLINK(اضافات!O30) -> 0 | I30: =HYPERLINK(خصومات!L30) -> 0 | J30: =SUM(D30,VALUE(E30),VALUE(F30),VALUE(G30)) -> 0 | K30: =VALUE(D30)+VALUE(G30)+VALUE(H30)-VALUE(I30) -> 0
B31: Spare | D31: 0 | E31: =HYPERLINK(اضافات!N31) -> 0 | F31: =HYPERLINK(اضافات!M31) -> 0 | G31: =HYPERLINK(اضافات!F31) -> 0 | H31: =HYPERLINK(اضافات!O31) -> 0 | I31: =HYPERLINK(خصومات!L31) -> 0 | J31: =SUM(D31,VALUE(E31),VALUE(F31),VALUE(G31)) -> 0 | K31: =VALUE(D31)+VALUE(G31)+VALUE(H31)-VALUE(I31) -> 0
B32: Spare | D32: 0 | E32: =HYPERLINK(اضافات!N32) -> 0 | F32: =HYPERLINK(اضافات!M32) -> 0 | G32: =HYPERLINK(اضافات!F32) -> 0 | H32: =HYPERLINK(اضافات!O32) -> 0 | I32: =HYPERLINK(خصومات!L32) -> 0 | J32: =SUM(D32,VALUE(E32),VALUE(F32),VALUE(G32)) -> 0 | K32: =VALUE(D32)+VALUE(G32)+VALUE(H32)-VALUE(I32) -> 0
A33: 8 | B33: أ/أحمد سيف الدين أبو بكر سري الدين | D33: 0 | E33: =HYPERLINK(اضافات!N33) -> 0 | F33: =HYPERLINK(اضافات!M33) -> 0 | G33: =HYPERLINK(اضافات!F33) -> 0 | H33: =HYPERLINK(اضافات!O33) -> 0 | I33: =HYPERLINK(خصومات!L33) -> 0 | J33: =SUM(D33,VALUE(E33),VALUE(F33),VALUE(G33)) -> 0 | K33: =VALUE(D33)+VALUE(G33)+VALUE(H33)-VALUE(I33) -> 0
A34: 9 | B34: أ/هاني أحمد الدالي | D34: 0 | E34: =HYPERLINK(اضافات!N34) -> 0 | F34: =HYPERLINK(اضافات!M34) -> 0 | G34: =HYPERLINK(اضافات!F34) -> 0 | H34: =HYPERLINK(اضافات!O34) -> 0 | I34: =HYPERLINK(خصومات!L34) -> 0 | J34: =SUM(D34,VALUE(E34),VALUE(F34),VALUE(G34)) -> 0 | K34: =VALUE(D34)+VALUE(G34)+VALUE(H34)-VALUE(I34) -> 0
A35: 10 | B35: أ/عبدالرحمن أحمد عبدالعزيز حسن | D35: 0 | E35: =HYPERLINK(اضافات!N35) -> 0 | F35: =HYPERLINK(اضافات!M35) -> 0 | G35: =HYPERLINK(اضافات!F35) -> 0 | H35: =HYPERLINK(اضافات!O35) -> 0 | I35: =HYPERLINK(خصومات!L35) -> 0 | J35: =SUM(D35,VALUE(E35),VALUE(F35),VALUE(G35)) -> 0 | K35: =VALUE(D35)+VALUE(G35)+VALUE(H35)-VALUE(I35) -> 0
B36: Spare | D36: 0 | E36: =HYPERLINK(اضافات!N36) -> 0 | F36: =HYPERLINK(اضافات!M36) -> 0 | G36: =HYPERLINK(اضافات!F36) -> 0 | H36: =HYPERLINK(اضافات!O36) -> 0 | I36: =HYPERLINK(خصومات!L36) -> 0 | J36: =SUM(D36,VALUE(E36),VALUE(F36),VALUE(G36)) -> 0 | K36: =VALUE(D36)+VALUE(G36)+VALUE(H36)-VALUE(I36) -> 0
B37: Spare | D37: 0 | E37: =HYPERLINK(اضافات!N37) -> 0 | F37: =HYPERLINK(اضافات!M37) -> 0 | G37: =HYPERLINK(اضافات!F37) -> 0 | H37: =HYPERLINK(اضافات!O37) -> 0 | I37: =HYPERLINK(خصومات!L37) -> 0 | J37: =SUM(D37,VALUE(E37),VALUE(F37),VALUE(G37)) -> 0 | K37: =VALUE(D37)+VALUE(G37)+VALUE(H37)-VALUE(I37) -> 0
B38: Spare | D38: 0 | E38: =HYPERLINK(اضافات!N38) -> 0 | F38: =HYPERLINK(اضافات!M38) -> 0 | G38: =HYPERLINK(اضافات!F38) -> 0 | H38: =HYPERLINK(اضافات!O38) -> 0 | I38: =HYPERLINK(خصومات!L38) -> 0 | J38: =SUM(D38,VALUE(E38),VALUE(F38),VALUE(G38)) -> 0 | K38: =VALUE(D38)+VALUE(G38)+VALUE(H38)-VALUE(I38) -> 0
B39: Spare | D39: 0 | E39: =HYPERLINK(اضافات!N39) -> 0 | F39: =HYPERLINK(اضافات!M39) -> 0 | G39: =HYPERLINK(اضافات!F39) -> 0 | H39: =HYPERLINK(اضافات!O39) -> 0 | I39: =HYPERLINK(خصومات!L39) -> 0 | J39: =SUM(D39,VALUE(E39),VALUE(F39),VALUE(G39)) -> 0 | K39: =VALUE(D39)+VALUE(G39)+VALUE(H39)-VALUE(I39) -> 0
B40: Spare | D40: 0 | E40: =HYPERLINK(اضافات!N40) -> 0 | F40: =HYPERLINK(اضافات!M40) -> 0 | G40: =HYPERLINK(اضافات!F40) -> 0 | H40: =HYPERLINK(اضافات!O40) -> 0 | I40: =HYPERLINK(خصومات!L40) -> 0 | J40: =SUM(D40,VALUE(E40),VALUE(F40),VALUE(G40)) -> 0 | K40: =VALUE(D40)+VALUE(G40)+VALUE(H40)-VALUE(I40) -> 0
...

Sheet مرتبات
A1: ديسمبر 2025
B2: الشهر | D2: 45870
A3: م | B3: الاسماء / Name | C3: - | D3: صافي الاتعاب والمرتبات / Salary | E3: إضافات غير مباشرة / In direct additions | F3: إضافات مباشرة / Direct Additions | G3: زيادة سنوية / Yearly Increase | H3: علاوات / Bouns | I3: خصومات / Deductions | J3: الإجمالي قبل الخصم GROSS | K3: الصافى بعد الخصم أو الزيادة NET | M3: طريقة الدفع | N3: رقم الحساب | O3: ملحوظات | P3: تحويل/شيك
A4: 1 | B4: د/هانى صلاح الدين محمد سري الدين | D4: 0 | E4: =HYPERLINK(اضافات!N4) -> 0 | F4: =HYPERLINK(اضافات!M4) -> 0 | G4: =HYPERLINK(اضافات!F4) -> 0 | H4: =HYPERLINK(اضافات!O4) -> 0 | I4: =HYPERLINK(خصومات!L4) -> 0 | J4: =SUM(D4,VALUE(E4),VALUE(F4),VALUE(G4)) -> 0 | K4: =VALUE(D4)+VALUE(G4)+VALUE(H4)-VALUE(I4) -> 0
A5: 2 | B5: أ/أميرة محمد على شريف | D5: 0 | E5: =HYPERLINK(اضافات!N5) -> 0 | F5: =HYPERLINK(اضافات!M5) -> 0 | G5: =HYPERLINK(اضافات!F5) -> 0 | H5: =HYPERLINK(اضافات!O5) -> 0 | I5: =HYPERLINK(خصومات!L5) -> 0 | J5: =SUM(D5,VALUE(E5),VALUE(F5),VALUE(G5)) -> 0 | K5: =VALUE(D5)+VALUE(G5)+VALUE(H5)-VALUE(I5) -> 0
A6: 3 | B6: أ/إيهاب حمدى ابراهيم | D6: 0 | E6: =HYPERLINK(اضافات!N6) -> 0 | F6: =HYPERLINK(اضافات!M6) -> 0 | G6: =HYPERLINK(اضافات!F6) -> 0 | H6: =HYPERLINK(اضافات!O6) -> 0 | I6: =HYPERLINK(خصومات!L6) -> 0 | J6: =SUM(D6,VALUE(E6),VALUE(F6),VALUE(G6)) -> 0 | K6: =VALUE(D6)+VALUE(G6)+VALUE(H6)-VALUE(I6) -> 0
B7: Spare | D7: 0 | E7: =HYPERLINK(اضافات!N7) -> 0 | F7: =HYPERLINK(اضافات!M7) -> 0 | G7: =HYPERLINK(اضافات!F7) -> 0 | H7: =HYPERLINK(اضافات!O7) -> 0 | I7: =HYPERLINK(خصومات!L7) -> 0 | J7: =SUM(D7,VALUE(E7),VALUE(F7),VALUE(G7)) -> 0 | K7: =VALUE(D7)+VALUE(G7)+VALUE(H7)-VALUE(I7) -> 0
B8: Spare | D8: 0 | E8: =HYPERLINK(اضافات!N8) -> 0 | F8: =HYPERLINK(اضافات!M8) -> 0 | G8: =HYPERLINK(اضافات!F8) -> 0 | H8: =HYPERLINK(اضافات!O8) -> 0 | I8: =HYPERLINK(خصومات!L8) -> 0 | J8: =SUM(D8,VALUE(E8),VALUE(F8),VALUE(G8)) -> 0 | K8: =VALUE(D8)+VALUE(G8)+VALUE(H8)-VALUE(I8) -> 0
B9: Spare | D9: 0 | E9: =HYPERLINK(اضافات!N9) -> 0 | F9: =HYPERLINK(اضافات!M9) -> 0 | G9: =HYPERLINK(اضافات!F9) -> 0 | H9: =HYPERLINK(اضافات!O9) -> 0 | I9: =HYPERLINK(خصومات!L9) -> 0 | J9: =SUM(D9,VALUE(E9),VALUE(F9),VALUE(G9)) -> 0 | K9: =VALUE(D9)+VALUE(G9)+VALUE(H9)-VALUE(I9) -> 0
B10: Spare | D10: 0 | E10: =HYPERLINK(اضافات!N10) -> 0 | F10: =HYPERLINK(اضافات!M10) -> 0 | G10: =HYPERLINK(اضافات!F10) -> 0 | H10: =HYPERLINK(اضافات!O10) -> 0 | I10: =HYPERLINK(خصومات!L10) -> 0 | J10: =SUM(D10,VALUE(E10),VALUE(F10),VALUE(G10)) -> 0 | K10: =VALUE(D10)+VALUE(G10)+VALUE(H10)-VALUE(I10) -> 0
B11: Spare | D11: 0 | E11: =HYPERLINK(اضافات!N11) -> 0 | F11: =HYPERLINK(اضافات!M11) -> 0 | G11: =HYPERLINK(اضافات!F11) -> 0 | H11: =HYPERLINK(اضافات!O11) -> 0 | I11: =HYPERLINK(خصومات!L11) -> 0 | J11: =SUM(D11,VALUE(E11),VALUE(F11),VALUE(G11)) -> 0 | K11: =VALUE(D11)+VALUE(G11)+VALUE(H11)-VALUE(I11) -> 0
B12: Spare | D12: 0 | E12: =HYPERLINK(اضافات!N12) -> 0 | F12: =HYPERLINK(اضافات!M12) -> 0 | G12: =HYPERLINK(اضافات!F12) -> 0 | H12: =HYPERLINK(اضافات!O12) -> 0 | I12: =HYPERLINK(خصومات!L12) -> 0 | J12: =SUM(D12,VALUE(E12),VALUE(F12),VALUE(G12)) -> 0 | K12: =VALUE(D12)+VALUE(G12)+VALUE(H12)-VALUE(I12) -> 0
B13: Spare | D13: 0 | E13: =HYPERLINK(اضافات!N13) -> 0 | F13: =HYPERLINK(اضافات!M13) -> 0 | G13: =HYPERLINK(اضافات!F13) -> 0 | H13: =HYPERLINK(اضافات!O13) -> 0 | I13: =HYPERLINK(خصومات!L13) -> 0 | J13: =SUM(D13,VALUE(E13),VALUE(F13),VALUE(G13)) -> 0 | K13: =VALUE(D13)+VALUE(G13)+VALUE(H13)-VALUE(I13) -> 0
B14: Spare | D14: 0 | E14: =HYPERLINK(اضافات!N14) -> 0 | F14: =HYPERLINK(اضافات!M14) -> 0 | G14: =HYPERLINK(اضافات!F14) -> 0 | H14: =HYPERLINK(اضافات!O14) -> 0 | I14: =HYPERLINK(خصومات!L14) -> 0 | J14: =SUM(D14,VALUE(E14),VALUE(F14),VALUE(G14)) -> 0 | K14: =VALUE(D14)+VALUE(G14)+VALUE(H14)-VALUE(I14) -> 0
B15: Spare | D15: 0 | E15: =HYPERLINK(اضافات!N15) -> 0 | F15: =HYPERLINK(اضافات!M15) -> 0 | G15: =HYPERLINK(اضافات!F15) -> 0 | H15: =HYPERLINK(اضافات!O15) -> 0 | I15: =HYPERLINK(خصومات!L15) -> 0 | J15: =SUM(D15,VALUE(E15),VALUE(F15),VALUE(G15)) -> 0 | K15: =VALUE(D15)+VALUE(G15)+VALUE(H15)-VALUE(I15) -> 0
B16: Spare | D16: 0 | E16: =HYPERLINK(اضافات!N16) -> 0 | F16: =HYPERLINK(اضافات!M16) -> 0 | G16: =HYPERLINK(اضافات!F16) -> 0 | H16: =HYPERLINK(اضافات!O16) -> 0 | I16: =HYPERLINK(خصومات!L16) -> 0 | J16: =SUM(D16,VALUE(E16),VALUE(F16),VALUE(G16)) -> 0 | K16: =VALUE(D16)+VALUE(G16)+VALUE(H16)-VALUE(I16) -> 0
B17: Spare | D17: 0 | E17: =HYPERLINK(اضافات!N17) -> 0 | F17: =HYPERLINK(اضافات!M17) -> 0 | G17: =HYPERLINK(اضافات!F17) -> 0 | H17: =HYPERLINK(اضافات!O17) -> 0 | I17: =HYPERLINK(خصومات!L17) -> 0 | J17: =SUM(D17,VALUE(E17),VALUE(F17),VALUE(G17)) -> 0 | K17: =VALUE(D17)+VALUE(G17)+VALUE(H17)-VALUE(I17) -> 0
A18: 3 | B18: اجمالي الشركاء | D18: =SUM(D4:D17) -> 0 | E18: =SUM(E4:E17) -> 0 | F18: =SUM(F4:F17) -> 0 | G18: =SUM(G4:G17) -> 0 | H18: =SUM(H4:H17) -> 0 | I18: =SUM(I4:I17) -> 0 | J18: =SUM(J4:J17) -> 0 | K18: =SUM(K4:K17) -> 0 | L18: =SUM(K4:K17) -> 0
A19: 1 | B19: أ/ناجى رمضان أمين محمد | D19: 0 | E19: =HYPERLINK(اضافات!N19) -> 0 | F19: =HYPERLINK(اضافات!M19) -> 0 | G19: =HYPERLINK(اضافات!F19) -> 0 | H19: =HYPERLINK(اضافات!O19) -> 0 | I19: =HYPERLINK(خصومات!L19) -> 0 | J19: =SUM(D19,VALUE(E19),VALUE(F19),VALUE(G19)) -> 0 | K19: =VALUE(D19)+VALUE(G19)+VALUE(H19)-VALUE(I19) -> 0
A20: 2 | B20: أ/محمد عبد العزيز عبدالحافظ | D20: 0 | E20: =HYPERLINK(اضافات!N20) -> 0 | F20: =HYPERLINK(اضافات!M20) -> 0 | G20: =HYPERLINK(اضافات!F20) -> 0 | H20: =HYPERLINK(اضافات!O20) -> 0 | I20: =HYPERLINK(خصومات!L20) -> 0 | J20: =SUM(D20,VALUE(E20),VALUE(F20),VALUE(G20)) -> 0 | K20: =VALUE(D20)+VALUE(G20)+VALUE(H20)-VALUE(I20) -> 0
A21: 3 | B21: أ/ أحمد سعيد أحمد محمد علي | D21: 0 | E21: =HYPERLINK(اضافات!N21) -> 0 | F21: =HYPERLINK(اضافات!M21) -> 0 | G21: =HYPERLINK(اضافات!F21) -> 0 | H21: =HYPERLINK(اضافات!O21) -> 0 | I21: =HYPERLINK(خصومات!L21) -> 0 | J21: =SUM(D21,VALUE(E21),VALUE(F21),VALUE(G21)) -> 0 | K21: =VALUE(D21)+VALUE(G21)+VALUE(H21)-VALUE(I21) -> 0
A22: 4 | B22: أ/منة الله البلتاجى | D22: 0 | E22: =HYPERLINK(اضافات!N22) -> 0 | F22: =HYPERLINK(اضافات!M22) -> 0 | G22: =HYPERLINK(اضافات!F22) -> 0 | H22: =HYPERLINK(اضافات!O22) -> 0 | I22: =HYPERLINK(خصومات!L22) -> 0 | J22: =SUM(D22,VALUE(E22),VALUE(F22),VALUE(G22)) -> 0 | K22: =VALUE(D22)+VALUE(G22)+VALUE(H22)-VALUE(I22) -> 0
A23: 5 | B23: أ/نهى عمرو محمد رضوان | D23: 0 | E23: =HYPERLINK(اضافات!N23) -> 0 | F23: =HYPERLINK(اضافات!M23) -> 0 | G23: =HYPERLINK(اضافات!F23) -> 0 | H23: =HYPERLINK(اضافات!O23) -> 0 | I23: =HYPERLINK(خصومات!L23) -> 0 | J23: =SUM(D23,VALUE(E23),VALUE(F23),VALUE(G23)) -> 0 | K23: =VALUE(D23)+VALUE(G23)+VALUE(H23)-VALUE(I23) -> 0
A24: 6 | B24: أ/عبد الله عمرو حافظ | D24: 0 | E24: =HYPERLINK(اضافات!N24) -> 0 | F24: =HYPERLINK(اضافات!M24) -> 0 | G24: =HYPERLINK(اضافات!F24) -> 0 | H24: =HYPERLINK(اضافات!O24) -> 0 | I24: =HYPERLINK(خصومات!L24) -> 0 | J24: =SUM(D24,VALUE(E24),VALUE(F24),VALUE(G24)) -> 0 | K24: =VALUE(D24)+VALUE(G24)+VALUE(H24)-VALUE(I24) -> 0
A25: 7 | B25: أ/محمد حمدى كامل | D25: 0 | E25: =HYPERLINK(اضافات!N25) -> 0 | F25: =HYPERLINK(اضافات!M25) -> 0 | G25: =HYPERLINK(اضافات!F25) -> 0 | H25: =HYPERLINK(اضافات!O25) -> 0 | I25: =HYPERLINK(خصومات!L25) -> 0 | J25: =SUM(D25,VALUE(E25),VALUE(F25),VALUE(G25)) -> 0 | K25: =VALUE(D25)+VALUE(G25)+VALUE(H25)-VALUE(I25) -> 0
B26: Spare | D26: 0 | E26: =HYPERLINK(اضافات!N26) -> 0 | F26: =HYPERLINK(اضافات!M26) -> 0 | G26: =HYPERLINK(اضافات!F26) -> 0 | H26: =HYPERLINK(اضافات!O26) -> 0 | I26: =HYPERLINK(خصومات!L26) -> 0 | J26: =SUM(D26,VALUE(E26),VALUE(F26),VALUE(G26)) -> 0 | K26: =VALUE(D26)+VALUE(G26)+VALUE(H26)-VALUE(I26) -> 0
B27: Spare | D27: 0 | E27: =HYPERLINK(اضافات!N27) -> 0 | F27: =HYPERLINK(اضافات!M27) -> 0 | G27: =HYPERLINK(اضافات!F27) -> 0 | H27: =HYPERLINK(اضافات!O27) -> 0 | I27: =HYPERLINK(خصومات!L27) -> 0 | J27: =SUM(D27,VALUE(E27),VALUE(F27),VALUE(G27)) -> 0 | K27: =VALUE(D27)+VALUE(G27)+VALUE(H27)-VALUE(I27) -> 0
B28: Spare | D28: 0 | E28: =HYPERLINK(اضافات!N28) -> 0 | F28: =HYPERLINK(اضافات!M28) -> 0 | G28: =HYPERLINK(اضافات!F28) -> 0 | H28: =HYPERLINK(اضافات!O28) -> 0 | I28: =HYPERLINK(خصومات!L28) -> 0 | J28: =SUM(D28,VALUE(E28),VALUE(F28),VALUE(G28)) -> 0 | K28: =VALUE(D28)+VALUE(G28)+VALUE(H28)-VALUE(I28) -> 0
B29: Spare | D29: 0 | E29: =HYPERLINK(اضافات!N29) -> 0 | F29: =HYPERLINK(اضافات!M29) -> 0 | G29: =HYPERLINK(اضافات!F29) -> 0 | H29: =HYPERLINK(اضافات!O29) -> 0 | I29: =HYPERLINK(خصومات!L29) -> 0 | J29: =SUM(D29,VALUE(E29),VALUE(F29),VALUE(G29)) -> 0 | K29: =VALUE(D29)+VALUE(G29)+VALUE(H29)-VALUE(I29) -> 0
B30: Spare | D30: 0 | E30: =HYPERLINK(اضافات!N30) -> 0 | F30: =HYPERLINK(اضافات!M30) -> 0 | G30: =HYPERLINK(اضافات!F30) -> 0 | H30: =HYPERLINK(اضافات!O30) -> 0 | I30: =HYPERLINK(خصومات!L30) -> 0 | J30: =SUM(D30,VALUE(E30),VALUE(F30),VALUE(G30)) -> 0 | K30: =VALUE(D30)+VALUE(G30)+VALUE(H30)-VALUE(I30) -> 0
B31: Spare | D31: 0 | E31: =HYPERLINK(اضافات!N31) -> 0 | F31: =HYPERLINK(اضافات!M31) -> 0 | G31: =HYPERLINK(اضافات!F31) -> 0 | H31: =HYPERLINK(اضافات!O31) -> 0 | I31: =HYPERLINK(خصومات!L31) -> 0 | J31: =SUM(D31,VALUE(E31),VALUE(F31),VALUE(G31)) -> 0 | K31: =VALUE(D31)+VALUE(G31)+VALUE(H31)-VALUE(I31) -> 0
B32: Spare | D32: 0 | E32: =HYPERLINK(اضافات!N32) -> 0 | F32: =HYPERLINK(اضافات!M32) -> 0 | G32: =HYPERLINK(اضافات!F32) -> 0 | H32: =HYPERLINK(اضافات!O32) -> 0 | I32: =HYPERLINK(خصومات!L32) -> 0 | J32: =SUM(D32,VALUE(E32),VALUE(F32),VALUE(G32)) -> 0 | K32: =VALUE(D32)+VALUE(G32)+VALUE(H32)-VALUE(I32) -> 0
A33: 8 | B33: أ/أحمد سيف الدين أبو بكر سري الدين | D33: 0 | E33: =HYPERLINK(اضافات!N33) -> 0 | F33: =HYPERLINK(اضافات!M33) -> 0 | G33: =HYPERLINK(اضافات!F33) -> 0 | H33: =HYPERLINK(اضافات!O33) -> 0 | I33: =HYPERLINK(خصومات!L33) -> 0 | J33: =SUM(D33,VALUE(E33),VALUE(F33),VALUE(G33)) -> 0 | K33: =VALUE(D33)+VALUE(G33)+VALUE(H33)-VALUE(I33) -> 0
A34: 9 | B34: أ/هاني أحمد الدالي | D34: 0 | E34: =HYPERLINK(اضافات!N34) -> 0 | F34: =HYPERLINK(اضافات!M34) -> 0 | G34: =HYPERLINK(اضافات!F34) -> 0 | H34: =HYPERLINK(اضافات!O34) -> 0 | I34: =HYPERLINK(خصومات!L34) -> 0 | J34: =SUM(D34,VALUE(E34),VALUE(F34),VALUE(G34)) -> 0 | K34: =VALUE(D34)+VALUE(G34)+VALUE(H34)-VALUE(I34) -> 0
A35: 10 | B35: أ/عبدالرحمن أحمد عبدالعزيز حسن | D35: 0 | E35: =HYPERLINK(اضافات!N35) -> 0 | F35: =HYPERLINK(اضافات!M35) -> 0 | G35: =HYPERLINK(اضافات!F35) -> 0 | H35: =HYPERLINK(اضافات!O35) -> 0 | I35: =HYPERLINK(خصومات!L35) -> 0 | J35: =SUM(D35,VALUE(E35),VALUE(F35),VALUE(G35)) -> 0 | K35: =VALUE(D35)+VALUE(G35)+VALUE(H35)-VALUE(I35) -> 0
B36: Spare | D36: 0 | E36: =HYPERLINK(اضافات!N36) -> 0 | F36: =HYPERLINK(اضافات!M36) -> 0 | G36: =HYPERLINK(اضافات!F36) -> 0 | H36: =HYPERLINK(اضافات!O36) -> 0 | I36: =HYPERLINK(خصومات!L36) -> 0 | J36: =SUM(D36,VALUE(E36),VALUE(F36),VALUE(G36)) -> 0 | K36: =VALUE(D36)+VALUE(G36)+VALUE(H36)-VALUE(I36) -> 0
B37: Spare | D37: 0 | E37: =HYPERLINK(اضافات!N37) -> 0 | F37: =HYPERLINK(اضافات!M37) -> 0 | G37: =HYPERLINK(اضافات!F37) -> 0 | H37: =HYPERLINK(اضافات!O37) -> 0 | I37: =HYPERLINK(خصومات!L37) -> 0 | J37: =SUM(D37,VALUE(E37),VALUE(F37),VALUE(G37)) -> 0 | K37: =VALUE(D37)+VALUE(G37)+VALUE(H37)-VALUE(I37) -> 0
B38: Spare | D38: 0 | E38: =HYPERLINK(اضافات!N38) -> 0 | F38: =HYPERLINK(اضافات!M38) -> 0 | G38: =HYPERLINK(اضافات!F38) -> 0 | H38: =HYPERLINK(اضافات!O38) -> 0 | I38: =HYPERLINK(خصومات!L38) -> 0 | J38: =SUM(D38,VALUE(E38),VALUE(F38),VALUE(G38)) -> 0 | K38: =VALUE(D38)+VALUE(G38)+VALUE(H38)-VALUE(I38) -> 0
B39: Spare | D39: 0 | E39: =HYPERLINK(اضافات!N39) -> 0 | F39: =HYPERLINK(اضافات!M39) -> 0 | G39: =HYPERLINK(اضافات!F39) -> 0 | H39: =HYPERLINK(اضافات!O39) -> 0 | I39: =HYPERLINK(خصومات!L39) -> 0 | J39: =SUM(D39,VALUE(E39),VALUE(F39),VALUE(G39)) -> 0 | K39: =VALUE(D39)+VALUE(G39)+VALUE(H39)-VALUE(I39) -> 0
B40: Spare | D40: 0 | E40: =HYPERLINK(اضافات!N40) -> 0 | F40: =HYPERLINK(اضافات!M40) -> 0 | G40: =HYPERLINK(اضافات!F40) -> 0 | H40: =HYPERLINK(اضافات!O40) -> 0 | I40: =HYPERLINK(خصومات!L40) -> 0 | J40: =SUM(D40,VALUE(E40),VALUE(F40),VALUE(G40)) -> 0 | K40: =VALUE(D40)+VALUE(G40)+VALUE(H40)-VALUE(I40) -> 0
...

Sheet اضافات
A1: اضافات شهرية
A2: # | B2: شهر ديسمبر 2025 | C2: بدلات تليفون / Phone Allowance | D2: بدلات انتقال / Transportation Allowance | E2: بدل سكن / Accommodation Allowance | F2: زيادة سنوية / Yearly Increase | G2: مكافئات سنوية / Annual Bonus | H2: مكافئات شهرية / Monthly Bonus | I2: قيمة التأمين الإجتماعي الممنوح / Given Social Insurance | J2: ضرائب إداريين/محامين / Taxs | K2: قيمة التأمين الصحي الممنوح \ Given Medical Insurance | L2: بدلات اخري / Allowances | M2: اجمالي إضافات مباشرة / Total Direct Allownces | N2: اجمالي إضافات غير مباشرة / Total InDirect Allownces | O2: اجمالي علاوات / Total Bouns | P2: اجمالي الإضافات / Total Allowances | Q2: ملحوظات
B3: شركاء
A4: =مرتبات2!A4 -> 1 | B4: =مرتبات!B4 -> د/هانى صلاح الدين محمد سري الدين | C4: 0 | D4: 0 | E4: 0 | F4: 0 | G4: 0 | H4: 0 | I4: 0 | J4: 0 | K4: 0 | L4: 0 | M4: =SUM(C4:E4)+L4 -> 0 | N4: =SUM(I4:K4) -> 0 | O4: =SUM(G4:H4) -> 0 | P4: =SUM(M4:O4) -> 0
A5: =مرتبات2!A5 -> 2 | B5: =مرتبات!B5 -> أ/أميرة محمد على شريف | C5: 0 | D5: 0 | E5: 0 | F5: 0 | G5: 0 | H5: 0 | I5: 0 | J5: 0 | K5: 0 | L5: 0 | M5: =SUM(C5:E5)+L5 -> 0 | N5: =SUM(I5:K5) -> 0 | O5: =SUM(G5:H5) -> 0 | P5: =SUM(M5:O5) -> 0
A6: =مرتبات2!A6 -> 3 | B6: =مرتبات!B6 -> أ/إيهاب حمدى ابراهيم | C6: 0 | D6: 0 | E6: 0 | F6: 0 | G6: 0 | H6: 0 | I6: 0 | J6: 0 | K6: 0 | L6: 0 | M6: =SUM(C6:E6)+L6 -> 0 | N6: =SUM(I6:K6) -> 0 | O6: =SUM(G6:H6) -> 0 | P6: =SUM(M6:O6) -> 0
A7: =مرتبات2!A7 -> 0 | B7: =مرتبات!B7 -> Spare | C7: 0 | D7: 0 | E7: 0 | F7: 0 | G7: 0 | H7: 0 | I7: 0 | J7: 0 | K7: 0 | L7: 0 | M7: =SUM(C7:E7)+L7 -> 0 | N7: =SUM(I7:K7) -> 0 | O7: =SUM(G7:H7) -> 0 | P7: =SUM(M7:O7) -> 0
A8: =مرتبات2!A8 -> 0 | B8: =مرتبات!B8 -> Spare | C8: 0 | D8: 0 | E8: 0 | F8: 0 | G8: 0 | H8: 0 | I8: 0 | J8: 0 | K8: 0 | L8: 0 | M8: =SUM(C8:E8)+L8 -> 0 | N8: =SUM(I8:K8) -> 0 | O8: =SUM(G8:H8) -> 0 | P8: =SUM(M8:O8) -> 0
A9: =مرتبات2!A9 -> 0 | B9: =مرتبات!B9 -> Spare | C9: 0 | D9: 0 | E9: 0 | F9: 0 | G9: 0 | H9: 0 | I9: 0 | J9: 0 | K9: 0 | L9: 0 | M9: =SUM(C9:E9)+L9 -> 0 | N9: =SUM(I9:K9) -> 0 | O9: =SUM(G9:H9) -> 0 | P9: =SUM(M9:O9) -> 0
A10: =مرتبات2!A10 -> 0 | B10: =مرتبات!B10 -> Spare | C10: 0 | D10: 0 | E10: 0 | F10: 0 | G10: 0 | H10: 0 | I10: 0 | J10: 0 | K10: 0 | L10: 0 | M10: =SUM(C10:E10)+L10 -> 0 | N10: =SUM(I10:K10) -> 0 | O10: =SUM(G10:H10) -> 0 | P10: =SUM(M10:O10) -> 0
A11: =مرتبات2!A11 -> 0 | B11: =مرتبات!B11 -> Spare | C11: 0 | D11: 0 | E11: 0 | F11: 0 | G11: 0 | H11: 0 | I11: 0 | J11: 0 | K11: 0 | L11: 0 | M11: =SUM(C11:E11)+L11 -> 0 | N11: =SUM(I11:K11) -> 0 | O11: =SUM(G11:H11) -> 0 | P11: =SUM(M11:O11) -> 0
A12: =مرتبات2!A12 -> 0 | B12: =مرتبات!B12 -> Spare | C12: 0 | D12: 0 | E12: 0 | F12: 0 | G12: 0 | H12: 0 | I12: 0 | J12: 0 | K12: 0 | L12: 0 | M12: =SUM(C12:E12)+L12 -> 0 | N12: =SUM(I12:K12) -> 0 | O12: =SUM(G12:H12) -> 0 | P12: =SUM(M12:O12) -> 0
A13: =مرتبات2!A13 -> 0 | B13: =مرتبات!B13 -> Spare | C13: 0 | D13: 0 | E13: 0 | F13: 0 | G13: 0 | H13: 0 | I13: 0 | J13: 0 | K13: 0 | L13: 0 | M13: =SUM(C13:E13)+L13 -> 0 | N13: =SUM(I13:K13) -> 0 | O13: =SUM(G13:H13) -> 0 | P13: =SUM(M13:O13) -> 0
A14: =مرتبات2!A14 -> 0 | B14: =مرتبات!B14 -> Spare | C14: 0 | D14: 0 | E14: 0 | F14: 0 | G14: 0 | H14: 0 | I14: 0 | J14: 0 | K14: 0 | L14: 0 | M14: =SUM(C14:E14)+L14 -> 0 | N14: =SUM(I14:K14) -> 0 | O14: =SUM(G14:H14) -> 0 | P14: =SUM(M14:O14) -> 0
A15: =مرتبات2!A15 -> 0 | B15: =مرتبات!B15 -> Spare | C15: 0 | D15: 0 | E15: 0 | F15: 0 | G15: 0 | H15: 0 | I15: 0 | J15: 0 | K15: 0 | L15: 0 | M15: =SUM(C15:E15)+L15 -> 0 | N15: =SUM(I15:K15) -> 0 | O15: =SUM(G15:H15) -> 0 | P15: =SUM(M15:O15) -> 0
... A17: =مرتبات2!A17 -> 0 | B17: =مرتبات!B17 -> Spare | C17: 0 | D17: 0 | E17: 0 | F17: 0 | G17: 0 | H17: 0 | I17: 0 | J17: 0 | K17: 0 | L17: 0 | M17: =SUM(C17:E17)+L17 -> 0 | N17: =SUM(I17:K17) -> 0 | O17: =SUM(G17:H17) -> 0 | P17: =SUM(M17:O17) -> 0
A18: =مرتبات2!A18 -> 3 | B18: محامين
A19: =مرتبات2!A19 -> 1 | B19: =مرتبات!B19 -> أ/ناجى رمضان أمين محمد | C19: 0 | D19: 0 | E19: 0 | F19: 0 | G19: 0 | H19: 0 | I19: 0 | J19: 0 | K19: 0 | L19: 0 | M19: =SUM(C19:E19)+L19 -> 0 | N19: =SUM(I19:K19) -> 0 | O19: =SUM(G19:H19) -> 0 | P19: =SUM(M19:O19) -> 0
A20: =مرتبات2!A20 -> 2 | B20: =مرتبات!B20 -> أ/محمد عبد العزيز عبدالحافظ | C20: 0 | D20: 0 | E20: 0 | F20: 0 | G20: 0 | H20: 0 | I20: 0 | J20: 0 | K20: 0 | L20: 0 | M20: =SUM(C20:E20)+L20 -> 0 | N20: =SUM(I20:K20) -> 0 | O20: =SUM(G20:H20) -> 0 | P20: =SUM(M20:O20) -> 0
A21: =مرتبات2!A21 -> 3 | B21: =مرتبات!B21 -> أ/ أحمد سعيد أحمد محمد علي | C21: 0 | D21: 0 | E21: 0 | F21: 0 | G21: 0 | H21: 0 | I21: 0 | J21: 0 | K21: 0 | L21: 0 | M21: =SUM(C21:E21)+L21 -> 0 | N21: =SUM(I21:K21) -> 0 | O21: =SUM(G21:H21) -> 0 | P21: =SUM(M21:O21) -> 0
A22: =مرتبات2!A22 -> 4 | B22: =مرتبات!B22 -> أ/منة الله البلتاجى | C22: 0 | D22: 0 | E22: 0 | F22: 0 | G22: 0 | H22: 0 | I22: 0 | J22: 0 | K22: 0 | L22: 0 | M22: =SUM(C22:E22)+L22 -> 0 | N22: =SUM(I22:K22) -> 0 | O22: =SUM(G22:H22) -> 0 | P22: =SUM(M22:O22) -> 0
A23: =مرتبات2!A23 -> 5 | B23: =مرتبات!B23 -> أ/نهى عمرو محمد رضوان | C23: 0 | D23: 0 | E23: 0 | F23: 0 | G23: 0 | H23: 0 | I23: 0 | J23: 0 | K23: 0 | L23: 0 | M23: =SUM(C23:E23)+L23 -> 0 | N23: =SUM(I23:K23) -> 0 | O23: =SUM(G23:H23) -> 0 | P23: =SUM(M23:O23) -> 0
A24: =مرتبات2!A24 -> 6 | B24: =مرتبات!B24 -> أ/عبد الله عمرو حافظ | C24: 0 | D24: 0 | E24: 0 | F24: 0 | G24: 0 | H24: 0 | I24: 0 | J24: 0 | K24: 0 | L24: 0 | M24: =SUM(C24:E24)+L24 -> 0 | N24: =SUM(I24:K24) -> 0 | O24: =SUM(G24:H24) -> 0 | P24: =SUM(M24:O24) -> 0
A25: =مرتبات2!A25 -> 7 | B25: =مرتبات!B25 -> أ/محمد حمدى كامل | C25: 0 | D25: 0 | E25: 0 | F25: 0 | G25: 0 | H25: 0 | I25: 0 | J25: 0 | K25: 0 | L25: 0 | M25: =SUM(C25:E25)+L25 -> 0 | N25: =SUM(I25:K25) -> 0 | O25: =SUM(G25:H25) -> 0 | P25: =SUM(M25:O25) -> 0
A26: =مرتبات2!A26 -> 0 | B26: =مرتبات!B26 -> Spare | C26: 0 | D26: 0 | E26: 0 | F26: 0 | G26: 0 | H26: 0 | I26: 0 | J26: 0 | K26: 0 | L26: 0 | M26: =SUM(C26:E26)+L26 -> 0 | N26: =SUM(I26:K26) -> 0 | O26: =SUM(G26:H26) -> 0 | P26: =SUM(M26:O26) -> 0
A27: =مرتبات2!A27 -> 0 | B27: =مرتبات!B27 -> Spare | C27: 0 | D27: 0 | E27: 0 | F27: 0 | G27: 0 | H27: 0 | I27: 0 | J27: 0 | K27: 0 | L27: 0 | M27: =SUM(C27:E27)+L27 -> 0 | N27: =SUM(I27:K27) -> 0 | O27: =SUM(G27:H27) -> 0 | P27: =SUM(M27:O27) -> 0
A28: =مرتبات2!A28 -> 0 | B28: =مرتبات!B28 -> Spare | C28: 0 | D28: 0 | E28: 0 | F28: 0 | G28: 0 | H28: 0 | I28: 0 | J28: 0 | K28: 0 | L28: 0 | M28: =SUM(C28:E28)+L28 -> 0 | N28: =SUM(I28:K28) -> 0 | O28: =SUM(G28:H28) -> 0 | P28: =SUM(M28:O28) -> 0
A29: =مرتبات2!A29 -> 0 | B29: =مرتبات!B29 -> Spare | C29: 0 | D29: 0 | E29: 0 | F29: 0 | G29: 0 | H29: 0 | I29: 0 | J29: 0 | K29: 0 | L29: 0 | M29: =SUM(C29:E29)+L29 -> 0 | N29: =SUM(I29:K29) -> 0 | O29: =SUM(G29:H29) -> 0 | P29: =SUM(M29:O29) -> 0
A30: =مرتبات2!A30 -> 0 | B30: =مرتبات!B30 -> Spare | C30: 0 | D30: 0 | E30: 0 | F30: 0 | G30: 0 | H30: 0 | I30: 0 | J30: 0 | K30: 0 | L30: 0 | M30: =SUM(C30:E30)+L30 -> 0 | N30: =SUM(I30:K30) -> 0 | O30: =SUM(G30:H30) -> 0 | P30: =SUM(M30:O30) -> 0
... A44: =مرتبات2!A44 -> 0 | B44: =مرتبات!B44 -> Spare | C44: 0 | D44: 0 | E44: 0 | F44: 0 | G44: 0 | H44: 0 | I44: 0 | J44: 0 | K44: 0 | L44: 0 | M44: =SUM(C44:E44)+L44 -> 0 | N44: =SUM(I44:K44) -> 0 | O44: =SUM(G44:H44) -> 0 | P44: =SUM(M44:O44) -> 0
A45: =مرتبات2!A45 -> 11 | B45: =مرتبات!B45 -> أ/حبيبة محمود سمير محمود عيسى | C45: 0 | D45: 0 | E45: 0 | F45: 0 | G45: 0 | H45: 0 | I45: 0 | J45: 0 | K45: 0 | L45: 0 | M45: =SUM(C45:E45)+L45 -> 0 | N45: =SUM(I45:K45) -> 0 | O45: =SUM(G45:H45) -> 0 | P45: =SUM(M45:O45) -> 0 | Q45: Refund for taxes deductions 3/3
A46: =مرتبات2!A46 -> 12 | B46: =مرتبات!B46 -> أ/احمد ابو العباس محمد الاتربي | C46: 0 | D46: 0 | E46: 0 | F46: 0 | G46: 0 | H46: 0 | I46: 0 | J46: 0 | K46: 0 | L46: 0 | M46: =SUM(C46:E46)+L46 -> 0 | N46: =SUM(I46:K46) -> 0 | O46: =SUM(G46:H46) -> 0 | P46: =SUM(M46:O46) -> 0
A47: =مرتبات2!A47 -> 13 | B47: =مرتبات!B47 -> أ/ليلي امين محمد امين طموم | C47: 0 | D47: 0 | E47: 0 | F47: 0 | G47: 0 | H47: 0 | I47: 0 | J47: 0 | K47: 0 | L47: 0 | M47: =SUM(C47:E47)+L47 -> 0 | N47: =SUM(I47:K47) -> 0 | O47: =SUM(G47:H47) -> 0 | P47: =SUM(M47:O47) -> 0
A48: =مرتبات2!A48 -> 14 | B48: =مرتبات!B48 -> أ/كريم ايمن محمد عادل | C48: 0 | D48: 0 | E48: 0 | F48: 0 | G48: 0 | H48: 0 | I48: 0 | J48: 0 | K48: 0 | L48: 0 | M48: =SUM(C48:E48)+L48 -> 0 | N48: =SUM(I48:K48) -> 0 | O48: =SUM(G48:H48) -> 0 | P48: =SUM(M48:O48) -> 0
A49: =مرتبات2!A49 -> 15 | B49: =مرتبات!B49 -> عمرو محمد عبدالحليم أبو سليم | C49: 0 | D49: 0 | E49: 0 | F49: 0 | G49: 0 | H49: 0 | I49: 0 | J49: 0 | K49: 0 | L49: 0 | M49: =SUM(C49:E49)+L49 -> 0 | N49: =SUM(I49:K49) -> 0 | O49: =SUM(G49:H49) -> 0 | P49: =SUM(M49:O49) -> 0
A50: =مرتبات2!A50 -> 0 | B50: =مرتبات!B50 -> Spare | C50: 0 | D50: 0 | E50: 0 | F50: 0 | G50: 0 | H50: 0 | I50: 0 | J50: 0 | K50: 0 | L50: 0 | M50: =SUM(C50:E50)+L50 -> 0 | N50: =SUM(I50:K50) -> 0 | O50: =SUM(G50:H50) -> 0 | P50: =SUM(M50:O50) -> 0
A51: =مرتبات2!A51 -> 0 | B51: =مرتبات!B51 -> Spare | C51: 0 | D51: 0 | E51: 0 | F51: 0 | G51: 0 | H51: 0 | I51: 0 | J51: 0 | K51: 0 | L51: 0 | M51: =SUM(C51:E51)+L51 -> 0 | N51: =SUM(I51:K51) -> 0 | O51: =SUM(G51:H51) -> 0 | P51: =SUM(M51:O51) -> 0
A52: =مرتبات2!A52 -> 0 | B52: =مرتبات!B52 -> Spare | C52: 0 | D52: 0 | E52: 0 | F52: 0 | G52: 0 | H52: 0 | I52: 0 | J52: 0 | K52: 0 | L52: 0 | M52: =SUM(C52:E52)+L52 -> 0 | N52: =SUM(I52:K52) -> 0 | O52: =SUM(G52:H52) -> 0 | P52: =SUM(M52:O52) -> 0
A53: =مرتبات2!A53 -> 0 | B53: =مرتبات!B53 -> Spare | C53: 0 | D53: 0 | E53: 0 | F53: 0 | G53: 0 | H53: 0 | I53: 0 | J53: 0 | K53: 0 | L53: 0 | M53: =SUM(C53:E53)+L53 -> 0 | N53: =SUM(I53:K53) -> 0 | O53: =SUM(G53:H53) -> 0 | P53: =SUM(M53:O53) -> 0
A54: =مرتبات2!A54 -> 0 | B54: =مرتبات!B54 -> Spare | C54: 0 | D54: 0 | E54: 0 | F54: 0 | G54: 0 | H54: 0 | I54: 0 | J54: 0 | K54: 0 | L54: 0 | M54: =SUM(C54:E54)+L54 -> 0 | N54: =SUM(I54:K54) -> 0 | O54: =SUM(G54:H54) -> 0 | P54: =SUM(M54:O54) -> 0
...

Sheet خصومات
B1: خصومات شهرية
A2: # | B2: شهر نوفمبر 2025 | C2: قيمة التأمين الصحي المخصوم / Deducted Medical Insurance | D2: ضرائب محامين / Laywers Taxs | E2: مسحوبات لبنوك أخرى / Other bank withdrawal | F2: مسحوبات/خصم من المرتب/الاتعاب / Loans or Deductions | G2: خصومات تليفون / Phone Deduction | H2: اجازات غير مدفوعة المرتب / Unpaid Vacation | I2: تأخيرات / Late | J2: خصومات تسجيل ساعات العمل / Time sheet | K2: خصومات اخري/ Other Deductions | L2: اجمالي الخصومات / Total Deductions | M2: ملحوظات
B3: شركاء
A4: =مرتبات2!A4 -> 1 | B4: =مرتبات!B4 -> د/هانى صلاح الدين محمد سري الدين | C4: 0 | D4: 0 | E4: 0 | F4: 0 | G4: 0 | H4: 0 | I4: 0 | J4: 0 | K4: 0 | L4: =SUM(C4:K4) -> 0
A5: =مرتبات2!A5 -> 2 | B5: =مرتبات!B5 -> أ/أميرة محمد على شريف | C5: 0 | D5: 0 | E5: 0 | F5: 0 | G5: 0 | H5: 0 | I5: 0 | J5: 0 | K5: 0 | L5: =SUM(C5:K5) -> 0
A6: =مرتبات2!A6 -> 3 | B6: =مرتبات!B6 -> أ/إيهاب حمدى ابراهيم | C6: 0 | D6: 0 | E6: 0 | F6: 0 | G6: 0 | H6: 0 | I6: 0 | J6: 0 | K6: 0 | L6: =SUM(C6:K6) -> 0
A7: =مرتبات2!A7 -> 0 | B7: =مرتبات!B7 -> Spare | C7: 0 | D7: 0 | E7: 0 | F7: 0 | G7: 0 | H7: 0 | I7: 0 | J7: 0 | K7: 0 | L7: =SUM(C7:K7) -> 0
A8: =مرتبات2!A8 -> 0 | B8: =مرتبات!B8 -> Spare | C8: 0 | D8: 0 | E8: 0 | F8: 0 | G8: 0 | H8: 0 | I8: 0 | J8: 0 | K8: 0 | L8: =SUM(C8:K8) -> 0
A9: =مرتبات2!A9 -> 0 | B9: =مرتبات!B9 -> Spare | C9: 0 | D9: 0 | E9: 0 | F9: 0 | G9: 0 | H9: 0 | I9: 0 | J9: 0 | K9: 0 | L9: =SUM(C9:K9) -> 0
A10: =مرتبات2!A10 -> 0 | B10: =مرتبات!B10 -> Spare | C10: 0 | D10: 0 | E10: 0 | F10: 0 | G10: 0 | H10: 0 | I10: 0 | J10: 0 | K10: 0 | L10: =SUM(C10:K10) -> 0
A11: =مرتبات2!A11 -> 0 | B11: =مرتبات!B11 -> Spare | C11: 0 | D11: 0 | E11: 0 | F11: 0 | G11: 0 | H11: 0 | I11: 0 | J11: 0 | K11: 0 | L11: =SUM(C11:K11) -> 0
A12: =مرتبات2!A12 -> 0 | B12: =مرتبات!B12 -> Spare | C12: 0 | D12: 0 | E12: 0 | F12: 0 | G12: 0 | H12: 0 | I12: 0 | J12: 0 | K12: 0 | L12: =SUM(C12:K12) -> 0
A13: =مرتبات2!A13 -> 0 | B13: =مرتبات!B13 -> Spare | C13: 0 | D13: 0 | E13: 0 | F13: 0 | G13: 0 | H13: 0 | I13: 0 | J13: 0 | K13: 0 | L13: =SUM(C13:K13) -> 0
A14: =مرتبات2!A14 -> 0 | B14: =مرتبات!B14 -> Spare | C14: 0 | D14: 0 | E14: 0 | F14: 0 | G14: 0 | H14: 0 | I14: 0 | J14: 0 | K14: 0 | L14: =SUM(C14:K14) -> 0
A15: =مرتبات2!A15 -> 0 | B15: =مرتبات!B15 -> Spare | C15: 0 | D15: 0 | E15: 0 | F15: 0 | G15: 0 | H15: 0 | I15: 0 | J15: 0 | K15: 0 | L15: =SUM(C15:K15) -> 0
... A17: =مرتبات2!A17 -> 0 | B17: =مرتبات!B17 -> Spare | C17: 0 | D17: 0 | E17: 0 | F17: 0 | G17: 0 | H17: 0 | I17: 0 | J17: 0 | K17: 0 | L17: =SUM(C17:K17) -> 0
A18: =مرتبات2!A18 -> 3 | B18: محامين
A19: =مرتبات2!A19 -> 1 | B19: =مرتبات!B19 -> أ/ناجى رمضان أمين محمد | C19: 0 | D19: 0 | E19: 0 | F19: 0 | G19: 0 | H19: 0 | I19: 0 | J19: 0 | K19: 0 | L19: =SUM(C19:K19) -> 0
A20: =مرتبات2!A20 -> 2 | B20: =مرتبات!B20 -> أ/محمد عبد العزيز عبدالحافظ | C20: 0 | D20: 0 | E20: 0 | F20: 0 | G20: 0 | H20: 0 | I20: 0 | J20: 0 | K20: 0 | L20: =SUM(C20:K20) -> 0
A21: =مرتبات2!A21 -> 3 | B21: =مرتبات!B21 -> أ/ أحمد سعيد أحمد محمد علي | C21: 0 | D21: 0 | E21: 0 | F21: 0 | G21: 0 | H21: 0 | I21: 0 | J21: 0 | K21: 0 | L21: =SUM(C21:K21) -> 0
A22: =مرتبات2!A22 -> 4 | B22: =مرتبات!B22 -> أ/منة الله البلتاجى | C22: 0 | D22: 0 | E22: 0 | F22: 0 | G22: 0 | H22: 0 | I22: 0 | J22: 0 | K22: 0 | L22: =SUM(C22:K22) -> 0
A23: =مرتبات2!A23 -> 5 | B23: =مرتبات!B23 -> أ/نهى عمرو محمد رضوان | C23: 0 | D23: 0 | E23: 0 | F23: 0 | G23: 0 | H23: 0 | I23: 0 | J23: 0 | K23: 0 | L23: =SUM(C23:K23) -> 0
A24: =مرتبات2!A24 -> 6 | B24: =مرتبات!B24 -> أ/عبد الله عمرو حافظ | C24: 0 | D24: 0 | E24: 0 | F24: 0 | G24: 0 | H24: 0 | I24: 0 | J24: 0 | K24: 0 | L24: =SUM(C24:K24) -> 0
A25: =مرتبات2!A25 -> 7 | B25: =مرتبات!B25 -> أ/محمد حمدى كامل | C25: 0 | D25: 0 | E25: 0 | F25: 0 | G25: 0 | H25: 0 | I25: 0 | J25: 0 | K25: 0 | L25: =SUM(C25:K25) -> 0
A26: =مرتبات2!A26 -> 0 | B26: =مرتبات!B26 -> Spare | C26: 0 | D26: 0 | E26: 0 | F26: 0 | G26: 0 | H26: 0 | I26: 0 | J26: 0 | K26: 0 | L26: =SUM(C26:K26) -> 0
A27: =مرتبات2!A27 -> 0 | B27: =مرتبات!B27 -> Spare | C27: 0 | D27: 0 | E27: 0 | F27: 0 | G27: 0 | H27: 0 | I27: 0 | J27: 0 | K27: 0 | L27: =SUM(C27:K27) -> 0
A28: =مرتبات2!A28 -> 0 | B28: =مرتبات!B28 -> Spare | C28: 0 | D28: 0 | E28: 0 | F28: 0 | G28: 0 | H28: 0 | I28: 0 | J28: 0 | K28: 0 | L28: =SUM(C28:K28) -> 0
A29: =مرتبات2!A29 -> 0 | B29: =مرتبات!B29 -> Spare | C29: 0 | D29: 0 | E29: 0 | F29: 0 | G29: 0 | H29: 0 | I29: 0 | J29: 0 | K29: 0 | L29: =SUM(C29:K29) -> 0
A30: =مرتبات2!A30 -> 0 | B30: =مرتبات!B30 -> Spare | C30: 0 | D30: 0 | E30: 0 | F30: 0 | G30: 0 | H30: 0 | I30: 0 | J30: 0 | K30: 0 | L30: =SUM(C30:K30) -> 0
... A55: =مرتبات2!A55 -> 0 | B55: =مرتبات!B55 -> Spare | C55: 0 | D55: 0 | E55: 0 | F55: 0 | G55: 0 | H55: 0 | I55: 0 | J55: 0 | K55: 0 | L55: =SUM(C55:K55) -> 0
A56: =مرتبات2!A56 -> 15 | B56: عاملين
A57: =مرتبات2!A57 -> 1 | B57: =مرتبات!B57 -> أ/دعاء عبد الدايم إبراهيم نصار | C57: 0 | D57: 0 | E57: 0 | F57: 0 | G57: 0 | H57: 0 | I57: 0 | J57: 0 | K57: 0 | L57: =SUM(C57:K57) -> 0
A58: =مرتبات2!A58 -> 2 | B58: =مرتبات!B58 -> أ/أحمد محمد رزق | C58: 0 | D58: 0 | E58: 0 | F58: 0 | G58: 0 | H58: 0 | I58: 0 | J58: 0 | K58: 0 | L58: =SUM(C58:K58) -> 0
A59: =مرتبات2!A59 -> 0 | B59: =مرتبات!B59 -> Manager Spare | C59: 0 | D59: 0 | E59: 0 | F59: 0 | G59: 0 | H59: 0 | I59: 0 | J59: 0 | K59: 0 | L59: =SUM(C59:K59) -> 0
A60: =مرتبات2!A60 -> 0 | B60: =مرتبات!B60 -> Manager Spare | C60: 0 | D60: 0 | E60: 0 | F60: 0 | G60: 0 | H60: 0 | I60: 0 | J60: 0 | K60: 0 | L60: =SUM(C60:K60) -> 0
A61: =مرتبات2!A61 -> 0 | B61: =مرتبات!B61 -> Manager Spare | C61: 0 | D61: 0 | E61: 0 | F61: 0 | G61: 0 | H61: 0 | I61: 0 | J61: 0 | K61: 0 | L61: =SUM(C61:K61) -> 0
A62: =مرتبات2!A62 -> 3 | B62: =مرتبات!B62 -> أ/خالد محمد حلمى | C62: 0 | D62: 0 | E62: 0 | F62: 0 | G62: 0 | H62: 0 | I62: 0 | J62: 0 | K62: 0 | L62: =SUM(C62:K62) -> 0
A63: =مرتبات2!A63 -> 4 | B63: =مرتبات!B63 -> أ/ نيرمين عصمت محمد حجازي | C63: 0 | D63: 0 | E63: 0 | F63: 0 | G63: 0 | H63: 0 | I63: 0 | J63: 0 | K63: 0 | L63: =SUM(C63:K63) -> 0
A64: =مرتبات2!A64 -> 0 | B64: =مرتبات!B64 -> Senior Spare | C64: 0 | D64: 0 | E64: 0 | F64: 0 | G64: 0 | H64: 0 | I64: 0 | J64: 0 | K64: 0 | L64: =SUM(C64:K64) -> 0
A65: =مرتبات2!A65 -> 0 | B65: =مرتبات!B65 -> Senior Spare | C65: 0 | D65: 0 | E65: 0 | F65: 0 | G65: 0 | H65: 0 | I65: 0 | J65: 0 | K65: 0 | L65: =SUM(C65:K65) -> 0
...

Sheet Pay Clip (AR)
H3: Row
C4: الإسم | D4: =INDEX(مرتبات2!B1:B1066,H4,1) -> أ/محمد عبدالجواد محمد | E4: الشهر | F4: =مرتبات2!D2 -> 45870 | H4: 81
C5: اتعاب/ راتب | D5: =SUM((INDEX(مرتبات2!D1:D1066,H4,1)),VALUE((INDEX(مرتبات2!G1:G1066,H4,1)))) -> 0
C6: مزايا مخصومة من إجمالي المرتب / اتعاب شهرية | E6: خصومات
C7: بدلات تليفون | D7: =INDEX(اضافات!C1:C1069,H4,1) -> 0 | E7: قيمة التأمين الصحي المخصوم | F7: =INDEX(خصومات!C1:C1069,H4,1) -> 0
C8: بدلات انتقال | D8: =INDEX(اضافات!D1:D1069,H4,1) -> 0 | E8: مسحوبات لبنوك أخرى | F8: =INDEX(خصومات!E1:E1070,H4,1) -> 0
C9: بدلات سكن | D9: =INDEX(اضافات!E1:E1069,H4,1) -> 0 | E9: مسحوبات/خصم من المرتب/الاتعاب | F9: =INDEX(خصومات!F1:F1071,H4,1) -> 0
C10: بدلات اخري | D10: =INDEX(اضافات!L1:L1069,H4,1) -> 0 | E10: تأخيرات | F10: =INDEX(خصومات!I1:I1072,H4,1) -> 0
C11: ضرائب | D11: =INDEX(اضافات!J1:J1069,H4,1) -> 0 | E11: اجازات غير مدفوعة المرتب | F11: =INDEX(خصومات!H1:H1073,H4,1) -> 0
C12: قيمة التأمين الإجتماعي الممنوح | D12: =INDEX(اضافات!I1:I1069,H4,1) -> 0 | E12: ضرائب محامين | F12: =INDEX(خصومات!D1:D1074,H4,1) -> 0
C13: قيمة التأمين الصحي الممنوح | D13: =INDEX(اضافات!K1:K1069,H4,1) -> 0 | E13: خصومات تليفون | F13: =INDEX(خصومات!G1:G1075,H4,1) -> 0
E14: خصومات تسجيل ساعات العمل | F14: =INDEX(خصومات!J1:J1076,H4,1) -> 0
E15: خصومات اخري | F15: =INDEX(خصومات!K1:K1077,H4,1) -> 0
C16: الإجمالي بالخصم والإضافة | D16: =D5+D7+D8+D9+D10+D11+D12+D13 -> 0
C17: إضافات على المرتب | D17: =SUM(D7:D15) -> 0
C18: بدلات | D18: =(SUM(F7:F15)) -> 0
C19: الصافي بعد الخصم والإضافة | D19: =D16-D17-D18 -> 0

Sheet Pay Clip (EN)
H3: Row
C4: Name | D4: =INDEX(مرتبات2!B1:B1066,H4,1) -> أ/ناجى رمضان أمين محمد | E4: Month | F4: =مرتبات2!D2 -> 45870 | H4: 19
C5: Salary\ Fees | D5: =SUM((INDEX(مرتبات2!D1:D1066,H4,1)),VALUE((INDEX(مرتبات2!G1:G1066,H4,1)))) -> 0
C6: Benefits deducted from the total Monthly Salary/Fees | E6: Deductions
C7: Phone Allowance | D7: =INDEX(اضافات!C1:C1069,H4,1) -> 0 | E7: Deducted Medical Insurance | F7: =INDEX(خصومات!C1:C1069,H4,1) -> 0
C8: Transportation Allowance | D8: =INDEX(اضافات!D1:D1069,H4,1) -> 0 | E8: Other bank withdrawal | F8: =INDEX(خصومات!E1:E1070,H4,1) -> 0
C9: Accommodation Allowance | D9: =INDEX(اضافات!E1:E1069,H4,1) -> 0 | E9: Loans or Deductions | F9: =INDEX(خصومات!F1:F1071,H4,1) -> 0
C10: Other Allowance | D10: =INDEX(اضافات!L1:L1069,H4,1) -> 0 | E10: Late Deduction | F10: =INDEX(خصومات!I1:I1072,H4,1) -> 0
C11: Taxs | D11: =INDEX(اضافات!J1:J1069,H4,1) -> 0 | E11: Unpaid Vacation | F11: =INDEX(خصومات!H1:H1073,H4,1) -> 0
C12: Given Social Insurance | D12: =INDEX(اضافات!I1:I1069,H4,1) -> 0 | E12: Lawyer Tax | F12: =INDEX(خصومات!D1:D1074,H4,1) -> 0
C13: Given Medical Insurance | D13: =INDEX(اضافات!K1:K1069,H4,1) -> 0 | E13: Phone Deduction | F13: =INDEX(خصومات!G1:G1075,H4,1) -> 0
E14: Time sheet Deduction | F14: =INDEX(خصومات!J1:J1076,H4,1) -> 0
E15: Other Deductions | F15: =INDEX(خصومات!K1:K1077,H4,1) -> 0
C16: Gross | D16: =D5+D7+D8+D9+D10+D11+D12+D13 -> 0
C17: Additions and Allowances | D17: =SUM(D7:D15) -> 0
C18: Deductions | D18: =(SUM(F7:F15)) -> 0
C19: NET | D19: =D16-D17-D18 -> 0
