Workbook

Sheet AllOffice
A1: ID | B1: Category | C1: Name in English | D1: الاسم بالعربية | E1: Job Title | F1: Department | G1: Date of Birth | H1: Graduation | L1: Social Insurance | M1: NationalID | O1: Bar Association | Q1: Tax Card | R1: Joining Date | S1: Address | V1: Extenstion | W1: Mobile Number | X1: Contract Type | Z1: Experience In | AB1: Experience Out | AD1: Status
F2: Division | H2: Certificate | I2: Section | J2: University / School | K2: Year | L2: الرقم التأميني | M2: Number | N2: Valid Till | O2: Number | P2: درجة القيد | S2: Address Details | T2: Region / City | U2: Governorate | X2: Contract Duration | Y2: Date of Renewal | Z2: Years | AA2: Month | AB2: Years | AC2: Month
A3: 1-1 | B3: Partner | C3: Dr. Hani Salah Mohamed Sarie Eldin | D3: د/ هانى صلاح محمد سرى الدين | E3: Managing Partner | F3: Partners | G3: 24246 | H3: Ph.D. | I3: International Business Law | J3: London / Cairo | K3: 1995 | L3: - | M3: 26605192101376 | N3: 46782 | O3: 72749 | P3: نقض | Q3: 261-915-487 | R3: 39083 | S3: 20 Saray Al Guizera | T3: Zamalek | U3: Cairo | V3: 400 | W3: 012-06001000 | X3: - | Y3: - | Z3: =DATEDIF(R3,TODAY(),"Y") -> 19 | AA3: =DATEDIF(R3,TODAY(),"Ym") -> 0 | AB3: 13 | AC3: 0 | AD3: Active
A4: 1-2 | B4: Partner | C4: Ms. Amira Mohamed Ali Sherif | D4: أ/ أميرة محمد على الشريف | E4: Senior Partner | F4: Partners | G4: 28398 | H4: Masters of Laws | I4: Private Law | J4: Cairo | K4: 2001 | L4: - | M4: 27709302101923 | N4: 46082 | O4: 479339 | P4: ابتدائي | Q4: 518-839-346 | R4: 39630 | S4: 321 A Megawra 2 - New Giza | T4: 6 of October | U4: Giza | V4: 450 | W4: 012-20800319 | X4: Service Agreement | Y4: - | Z4: =DATEDIF(R4,TODAY(),"Y") -> 17 | AA4: =DATEDIF(R4,TODAY(),"Ym") -> 6 | AB4: 9 | AC4: 0 | AD4: Active
A5: 2-4 | B5: Partner | C5: Ihab Hamdy Ibrahim Imam | D5: ايهاب حمدى ابراهيم امام | E5: Litigation Partner | F5: Partners | G5: 32039 | H5: Bachelor of Laws | I5: Arabic | J5: Ain Shams | K5: 2008 | L5: - | M5: 28709190101694 | N5: 46358 | O5: 393620 | P5: استئناف | Q5: 323-946-933 | R5: 41609 | S5: 44 Al Manial Museum - Manial | T5: Masr Al Adeema | U5: Cairo | V5: 457 | W5: 012-24222313 | X5: Service Agreement | Y5: - | Z5: =DATEDIF(R5,TODAY(),"Y") -> 12 | AA5: =DATEDIF(R5,TODAY(),"Ym") -> 1 | AB5: 12 | AC5: 0 | AD5: Active
A6: 2-1 | B6: Lawyer | C6: Mohamed Abd El Aziz Abd El Hafez Mohamed | D6: محمد عبد العزيز عبد الحافظ محمد | E6: Litigation Senior Associate | F6: Litigation | G6: 27212 | H6: Bachelor of Laws | I6: Arabic | J6: Tanta | K6: 1996 | L6: - | M6: 27407022102898 | N6: 11890 | O6: 174535 | P6: نقض | Q6: 232-512-620 | R6: 40199 | S6: 12 Bahr El Ghazal St. | T6: Al Agouza | U6: Giza | V6: 473 | W6: 012-81110096 | X6: Service Agreement | Y6: - | Z6: =DATEDIF(R6,TODAY(),"Y") -> 15 | AA6: =DATEDIF(R6,TODAY(),"Ym") -> 11 | AB6: 5 | AC6: 3 | AD6: Active
A7: 2-2 | B7: Lawyer | C7: Mohamed Hamdy Kamel Mostafa | D7: محمد حمدى كامل مصطفى | E7: Senior Associate Corporate Procedures | F7: Banking & Procedures | G7: 31929 | H7: Bachelor of Laws | I7: Arabic | J7: Ain Shams | K7: 2008 | L7: - | M7: 28706010116291 | N7: 46836 | O7: 425131 | P7: استئناف | Q7: 407-451-579 | R7: 40211 | S7: 6 Abbas Al Sherif - Helmyet Al Zaitoun | T7: Ain Shams | U7: Cairo | V7: 454 | W7: 012-20800325 | X7: Service Agreement | Y7: - | Z7: =DATEDIF(R7,TODAY(),"Y") -> 15 | AA7: =DATEDIF(R7,TODAY(),"Ym") -> 11 | AB7: 0 | AC7: 0 | AD7: Active
A8: 2-3 | B8: Lawyer | C8: Menna Allah Nabil Mohamed El Beltagy | D8: منه الله نبيل محمد البلتاجى | E8: Senior Associate | F8: Arbitration | G8: 32050 | H8: Bachelor of Laws | I8: English | J8: Cairo | K8: 2008 | L8: - | M8: 28709300100265 | N8: 46099 | O8: 416877 | P8: ابتدائي | Q8: 411-839-799 | R8: 41420 | S8: 4 El Saloly St. | T8: Al Doqi | U8: Giza | V8: 455 | W8: 010-01760945 | X8: Service Agreement | Y8: - | Z8: =DATEDIF(R8,TODAY(),"Y") -> 12 | AA8: =DATEDIF(R8,TODAY(),"Ym") -> 7 | AB8: 4 | AC8: 0 | AD8: Active
A9: 2-5 | B9: Lawyer | C9: Noha Amr Mohamed Radwan | D9: نهى عمرو محمد رضوان | E9: Senior Associate | F9: Arbitration | G9: 33426 | H9: Bachelor of Laws | I9: French | J9: Sorbonne | K9: 2012 | L9: - | M9: 29107072104682 | N9: 46345 | O9: 527331 | P9: ابتدائي | Q9: 672-816-644 | R9: 41854 | S9: 44 Al Manial Museum - Manial | T9: Masr Al Adeema | U9: Cairo | V9: 409 | W9: 010-05697822 | X9: Service Agreement | Y9: - | Z9: =DATEDIF(R9,TODAY(),"Y") -> 11 | AA9: =DATEDIF(R9,TODAY(),"Ym") -> 5 | AB9: 22 | AC9: 0 | AD9: Active
A10: 2-6 | B10: Lawyer | C10: Nagy Ramdan Amin Mohamed | D10: ناجى رمضان امين محمد | E10: Litigation Senior Associate | F10: Litigation | G10: 25625 | H10: Bachelor of Laws | I10: Arabic | J10: Ain Shams | K10: 1991 | L10: - | M10: 27002260101051 | N10: 47457 | O10: 116022 | P10: استئناف | Q10: 220-218-188 | R10: 42043 | S10: 10-A Al Houd St. | T10: Abdeen | U10: Cairo | V10: 456 | W10: 012-20800314 | X10: Service Agreement | Y10: - | Z10: =DATEDIF(R10,TODAY(),"Y") -> 10 | AA10: =DATEDIF(R10,TODAY(),"Ym") -> 10 | AB10: 12 | AC10: 0 | AD10: Active
A11: 2-7 | B11: Lawyer | C11: Hany Ahmed Abd El Meged Mourad El Daly | D11: هانى احمد عبد المجيد مراد الدالي | E11: Associate | F11: Litigation | G11: 31073 | H11: Bachelor of Laws | I11: Arabic | J11: Cairo | K11: 2006 | L11: - | M11: 28501262101031 | N11: 47482 | O11: 361956 | P11: استئناف | Q11: 352-188-693 | R11: 42644 | S11: 12 Monshat El Bakari Village | T11: Haram | U11: Giza | V11: 421 | W11: 011-51015555 - 012-87111142 | X11: Service Agreement | Y11: - | Z11: =DATEDIF(R11,TODAY(),"Y") -> 9 | AA11: =DATEDIF(R11,TODAY(),"Ym") -> 3 | AB11: 2 | AC11: 0 | AD11: Active
A12: 2-8 | B12: Lawyer | C12: Ahmed Seif Eldin Abo Bakr Sarie Eldin | D12: احمد سيف الدين ابو بكر سرى الدين | E12: Associate | F12: Banking & Procedures | G12: 28890 | H12: Bachelor of Laws | I12: Arabic | J12: Police Academy | K12: 2000 | L12: 77052671 | M12: 27902040103975 | N12: 46056 | O12: - | P12: غير مقيد | Q12: - | R12: 44197 | S12: 1 Helal Ebn Omaya St. from Amaar Ebn Yasser St. | T12: El Nozha | U12: Cairo | V12: 405 | W12: 011-11066255 | X12: Renewal for One Year | Y12: =Contracts!D230 -> 46203 | Z12: =DATEDIF(R12,TODAY(),"Y") -> 5 | AA12: =DATEDIF(R12,TODAY(),"Ym") -> 0 | AB12: 0 | AC12: 0 | AD12: Active
A13: 2-9 | B13: Lawyer | C13: Ahmed Said Ahmed Mohamed Ali | D13: احمد سعيد احمد محمد على | E13: Senior Associate | F13: Litigation | G13: 27975 | H13: Bachelor of Laws | I13: Arabic | J13: Alexandria | K13: 1999 | L13: - | M13: 27608030201213 | N13: 46050 | O13: 209012 | P13: نقض | Q13: 274-097-028 | R13: 43534 | S13: 311 Hay 2 - Megawra 5 | T13: Sheikh Zayed | U13: Giza | V13: 420 | W13: 012-20800351 | X13: Service Agreement | Y13: - | Z13: =DATEDIF(R13,TODAY(),"Y") -> 6 | AA13: =DATEDIF(R13,TODAY(),"Ym") -> 9 | AB13: 1 | AC13: 0 | AD13: Active
A14: 2-10 | B14: Lawyer | C14: Mahmoud Shabaan Mahmoud Hassan | D14: محمود شعبان محمود حسن | E14: Associate | F14: Litigation | G14: 34357 | H14: Bachelor of Laws | I14: Arabic | J14: Cairo | K14: 2015 | L14: - | M14: 29401232101796 | N14: 46842 | O14: 627767 | P14: ابتدائي | Q14: 628-842-058 | R14: 44236 | S14: Om Denar Village | T14: Monshaat Al Qanater | U14: Giza | V14: 429 | W14: 010-01080373 | X14: Service Agreement | Y14: - | Z14: =DATEDIF(R14,TODAY(),"Y") -> 4 | AA14: =DATEDIF(R14,TODAY(),"Ym") -> 10 | AB14: 0 | AC14: 0 | AD14: Resigned
A15: 2-11 | B15: Lawyer | C15: Omar Essam Hanafy Mahmoud | D15: عمر عصام حنفى محمود | E15: Junior Associate | F15: Capital Market | G15: 36167 | H15: Bachelor of Laws | I15: English | J15: Cairo | K15: 2020 | L15: - | M15: 29901070103172 | N15: 11098 | O15: 654196 | P15: ابتدائي | Q15: 652-844-383 | R15: 44409 | S15: Villa 177 Tawasoat Al Shamalya | T15: 6 of October | U15: Giza | V15: 435 | W15: 010-66533934 | X15: Service Agreement | Z15: =DATEDIF(R15,TODAY(),"Y") -> 4 | AA15: =DATEDIF(R15,TODAY(),"Ym") -> 5 | AB15: 0 | AC15: 0 | AD15: Resigned
A16: 2-12 | B16: Lawyer | C16: Mohamed Wally Abd El Hady Mohamed | D16: محمد والى عبد الهادى محمد | E16: Associate | F16: Banking & Procedures | G16: 33307 | H16: Bachelor of Laws | I16: English | J16: Beni Suef | K16: 2012 | L16: - | M16: 29103102303116 | N16: 46988 | O16: 585163 | P16: ابتدائي | Q16: 728-681-390 | R16: 44563 | S16: Baghous Village | T16: Al Fayoum | U16: Al Fayoum | V16: 453 | W16: 010-67572777 | X16: Service Agreement | Z16: =DATEDIF(R16,TODAY(),"Y") -> 4 | AA16: =DATEDIF(R16,TODAY(),"Ym") -> 0 | AB16: 0 | AC16: 0 | AD16: Resigned
A17: 2-13 | B17: Lawyer | C17: Yasmine Safwat Salah Eldin Ibrahim | D17: ياسمين صفوت صلاح الدين ابراهيم | E17: Junior Associate | F17: Capital Market | G17: 35643 | H17: Bachelor of Laws | I17: Arabic | J17: Cairo | K17: 2020 | L17: - | M17: 29708012109701 | N17: 11232 | O17: 705560 | P17: جدول عام | Q17: 756-421-918 | R17: 44850 | S17: 33 Babel St. | T17: Al Doqi | U17: Giza | V17: 408 | W17: 011-00702019 | X17: Service Agreement | Y17: - | Z17: =DATEDIF(R17,TODAY(),"Y") -> 3 | AA17: =DATEDIF(R17,TODAY(),"Ym") -> 2 | AB17: 0 | AC17: 0 | AD17: Resigned
A18: 2-14 | B18: Lawyer | C18: Habiba Mahmoud Samir Mahmoud Issa | D18: حبيبه محمود سمير محمود عيسى | E18: Junior Associate | F18: Capital Market | G18: 36510 | H18: Bachelor of Laws | I18: English | J18: Cairo | K18: 2022 | L18: - | M18: 29912162101267 | N18: 48107 | O18: 719204 | P18: جدول عام | Q18: - | R18: 44983 | S18: Villa 84 - Belle Ville Compound | T18: Sheikh Zayed | U18: Giza | V18: 407 | W18: 010-07261601 | X18: Service Agreement | Y18: - | Z18: =DATEDIF(R18,TODAY(),"Y") -> 2 | AA18: =DATEDIF(R18,TODAY(),"Ym") -> 10 | AB18: 0 | AC18: 0 | AD18: Active
A19: 2-15 | B19: Lawyer | C19: Farah Abd Allah Mahmoud Al Nahas | D19: فرح عبدالله محمود النحاس | E19: Senior Associate | F19: Capital Market | G19: 32903 | H19: Bachelor of Laws | I19: French | J19: Sorbonne | K19: 2010 | L19: - | M19: 29001300100207 | N19: 45740 | O19: 482737 | P19: ابتدائي | Q19: 477-199-348 | R19: 45096 | S19: 382 El Seyaheya Al Rabaa | T19: 6 of October | U19: Giza | V19: 448 | W19: 012-21596311 | X19: Service Agreement | Y19: - | Z19: =DATEDIF(R19,TODAY(),"Y") -> 2 | AA19: =DATEDIF(R19,TODAY(),"Ym") -> 6 | AB19: 0 | AC19: 0 | AD19: Resigned
A20: 2-16 | B20: Lawyer | C20: Abdel Rahman Ahmed Abdel Aziz Hassan | D20: عبد الرحمن احمد عبد العزيز حسن | E20: Associate | F20: Litigation | G20: 33539 | H20: Bachelor of Laws | I20: Arabic | J20: Beni Suef | K20: 2012 | L20: - | M20: 29110282301155 | N20: 48248 | O20: 525032 | P20: استئناف | Q20: 518-620-220 | R20: 45125 | S20: Hassan Nafea St. Beside Metro - Faisal | T20: Haram | U20: Giza | V20: 459 | W20: 010-09135242 | X20: Service Agreement | Y20: - | Z20: =DATEDIF(R20,TODAY(),"Y") -> 2 | AA20: =DATEDIF(R20,TODAY(),"Ym") -> 5 | AB20: 5 | AC20: 0 | AD20: Active
A21: 2-17 | B21: Lawyer | C21: Ahmed Abu El Abbas Mohamed Ahmed El Etreby | D21: احمد ابو العباس محمد احمد الاتربى | E21: Junior Associate | F21: Capital Market | G21: 35688 | H21: Bachelor of Laws | I21: Arabic | J21: Cairo | K21: 2019 | L21: - | M21: 29709158800274 | N21: 47462 | O21: 682192 | P21: جدول عام | Q21: 759-791-767 | R21: 45323 | S21: 10 Abu El Mawaheb St. Agouza | T21: Al Doqi | U21: Giza | V21: 435 | W21: 011-11469162 | X21: Service Agreement | Y21: - | Z21: =DATEDIF(R21,TODAY(),"Y") -> 1 | AA21: =DATEDIF(R21,TODAY(),"Ym") -> 11 | AB21: 0 | AC21: 0 | AD21: Active
A22: 2-18 | B22: Lawyer | C22: Laila Amin Mohamed Amin Tomoum | D22: ليلي امين محمد امين طموم | E22: Junior Associate | F22: Capital Market | G22: 37222 | H22: Bachelor of Laws | I22: English | J22: GUC | K22: 2023 | L22: - | M22: 30111272101141 | N22: 46732 | O22: 748829 | P22: جدول عام | Q22: 762-270-713 | R22: 45354 | S22: 11 Amin Bek El Rafai St. - El Mesaha Square | T22: Al Doqi | U22: Giza | V22: 436 | W22: 012-79697641 | X22: Service Agreement | Y22: - | Z22: =DATEDIF(R22,TODAY(),"Y") -> 1 | AA22: =DATEDIF(R22,TODAY(),"Ym") -> 10 | AB22: 0 | AC22: 0 | AD22: Resigned
A23: 2-19 | B23: Lawyer | C23: Hussien Sherif Mohamed Monier Amer | D23: حسين شريف محمد منير عامر | E23: Associate | F23: Banking & Procedures | G23: 35383 | H23: Master of Laws | I23: Professional Legal Practice | J23: University of Law | K23: 2021 | L23: - | M23: 29611142103697 | N23: 47469 | O23: 710391 | P23: جدول عام | Q23: - | R23: 45397 | S23: Villa 26 Telal Al Guziera | T23: Sheikh Zayed | U23: Giza | V23: 406 | W23: 010-00969141 | X23: Service Agreement | Y23: - | Z23: =DATEDIF(R23,TODAY(),"Y") -> 1 | AA23: =DATEDIF(R23,TODAY(),"Ym") -> 8 | AB23: 0 | AC23: 0 | AD23: Resigned
A24: 2-20 | B24: Lawyer | C24: Kareem Ayman Mohamed Adel | D24: كريم ايمن محمد عادل | E24: Junior Associate | F24: Banking & Procedures | G24: 37120 | H24: Bachelor of Laws | I24: English | J24: Cairo | K24: 2023 | L24: - | M24: 30108170103254 | N24: 47694 | O24: 753438 | P24: جدول عام | Q24: 768-202-689 | R24: 45536 | S24: 41516 Zayed Regency Compound | T24: Sheikh Zayed | U24: Giza | V24: 453 | W24: 012-01107220 | X24: Service Agreement | Y24: - | Z24: =DATEDIF(R24,TODAY(),"Y") -> 1 | AA24: =DATEDIF(R24,TODAY(),"Ym") -> 4 | AB24: 0 | AC24: 0 | AD24: Active
A25: 2-21 | B25: Lawyer | C25: Abd Allah Amr Abd El Aziz Mohamed Hafez | D25: عبد الله عمرو عبد العزيز محمد حافظ | E25: Senior Associate | F25: Banking & Procedures | G25: 34680 | H25: Bachelor of Laws | I25: Global Law | J25: Tilburg / Netherlands | K25: 2016 | L25: - | M25: 29412120102597 | N25: 46050 | O25: 651901 | P25: ابتدائي | Q25: 619-180-439 | R25: 45690 | S25: Villa A1D Royaa Compound - Waslet Dahshour | T25: Sheikh Zayed | U25: Giza | V25: 406 | W25: 010-05171896 | X25: Service Agreement | Y25: - | Z25: =DATEDIF(R25,TODAY(),"Y") -> 0 | AA25: =DATEDIF(R25,TODAY(),"Ym") -> 11 | AB25: 7 | AC25: 0 | AD25: Active
A26: 2-22 | B26: Lawyer | C26: Amr Mohamed Abdel Haleem Abdo Sleem | D26: عمرو محمد عبد الحليم عبده سليم | E26: Junior Associate | F26: Litigation | G26: 36054 | H26: Bachelor of Laws | I26: Arabic | J26: Cairo | K26: 2022 | L26: - | M26: 29809161304657 | N26: 47813 | O26: 774413 | P26: جدول عام | Q26: - | R26: 45872 | S26: 19 Fahmy Street | T26: Tahrir Square | U26: Cairo | V26: 429 | W26: 011-27539043 | X26: Service Agreement | Y26: - | Z26: =DATEDIF(R26,TODAY(),"Y") -> 0 | AA26: =DATEDIF(R26,TODAY(),"Ym") -> 5 | AB26: 0 | AC26: 0 | AD26: Active
A27: 3-1 | B27: Admin | C27: Ms. Doaa Abd El Dayem Ibrahim Nassar | D27: أ/ دعاء عبد الدايم ابراهيم نصار | E27: Admin & HR Manager | F27: Directors | G27: 31635 | H27: Bachlor of Arts | I27: Language and Translation | J27: 6 of October | K27: 2008 | L27: 3049507 | M27: 28608110105022 | N27: 46996 | O27: N/A | P27: N/A | Q27: N/A | R27: 41107 | S27: 191 Hay 1 Megawra 8 | T27: Sheikh Zayed | U27: Giza | V27: 410 | W27: 012-20046660 | X27: Renewal for One Year | Y27: =Contracts!D3 -> 46219 | Z27: =DATEDIF(R27,TODAY(),"Y") -> 13 | AA27: =DATEDIF(R27,TODAY(),"Ym") -> 5 | AB27: 4 | AC27: 0 | AD27: Active
A28: 3-2 | B28: Admin | C28: Khaled Mohamed Helmy Mohamed Yousry Abd Rabo | D28: خالد محمد حلمى محمد يسرى عبد ربه | E28: Senior Systems Engineer | F28: IT | G28: 31982 | H28: Bachelor of Engineering | I28: Electrical Engineering | J28: High Technology Institution | K28: 2010 | L28: 66494942 | M28: 28707248800056 | N28: 47314 | O28: 49/8708270/2010/1 | P28: N/A | Q28: N/A | R28: 41660 | S28: 9 Megawra 27 - Al Rehab | T28: New Cairo | U28: Cairo | V28: 490 | W28: 010-07847333 | X28: Renewal for One Year | Y28: =Contracts!D18 -> 46042 | Z28: =DATEDIF(R28,TODAY(),"Y") -> 11 | AA28: =DATEDIF(R28,TODAY(),"Ym") -> 11 | AB28: 1 | AC28: 8 | AD28: Active
A29: 3-3 | B29: Admin | C29: Ahmed Mohamed Rezk Mohamed | D29: احمد محمد رزق محمد | E29: Accounting Manager | F29: Accounting | G29: 32661 | H29: Bachlor of Commerce | I29: Accounting - English | J29: Ain Shams | K29: 2011 | L29: 26801623 | M29: 28906020101215 | N29: 46649 | O29: N/A | P29: N/A | Q29: N/A | R29: 43009 | S29: 76 Hay 8 - Megawra 3 | T29: 6 of October | U29: Giza | V29: 451 | W29: 011-19895595 | X29: Renewal for One Year | Y29: =Contracts!D33 -> 46126 | Z29: =DATEDIF(R29,TODAY(),"Y") -> 8 | AA29: =DATEDIF(R29,TODAY(),"Ym") -> 3 | AB29: 5 | AC29: 2 | AD29: Active
A30: 3-4 | B30: Admin | C30: Irene Zaghloul Nazier Mohareb | D30: ايرين زغلول نظير محارب | E30: Executive Assistant | F30: Admin/Secertary | G30: 29779 | H30: Bachlor of Arts | I30: English Literature | J30: Cairo | K30: 2002 | L30: 55930451 | M30: 28107122101805 | N30: 45792 | O30: N/A | P30: N/A | Q30: N/A | R30: 43814 | S30: 3 Makka St. - Marioteya - Faisal | T30: Haram | U30: Giza | V30: 412 | W30: 012-25874918 | X30: Revewal for Six Month | Y30: 45275 | Z30: =DATEDIF(R30,TODAY(),"Y") -> 6 | AA30: =DATEDIF(R30,TODAY(),"Ym") -> 0 | AB30: 0 | AC30: 0 | AD30: Resigned
A31: 3-5 | B31: Admin | C31: Nermine Essmat Mohamed Hegazy | D31: نرمين عصمت محمد حجازى | E31: Senior Admin Assistant | F31: Admin/Secertary | G31: 27900 | H31: Bachlor of Commerce | I31: Accounting | J31: Cairo | K31: 1999 | L31: 55306579 | M31: 27605208800184 | N31: 46728 | O31: N/A | P31: N/A | Q31: N/A | R31: 43223 | S31: 4 Guhayna St. | T31: Al Doqi | U31: Giza | V31: 411 | W31: 010-00118805 | X31: Renewal for One Year | Y31: =Contracts!D52 -> 46162 | Z31: =DATEDIF(R31,TODAY(),"Y") -> 7 | AA31: =DATEDIF(R31,TODAY(),"Ym") -> 8 | AB31: 13 | AC31: 0 | AD31: Active
A32: 3-6 | B32: Admin | C32: Marwa Sherif Abd El Hamid Salama | D32: مروة شريف عبد الحميد سلامة | E32: Executive Assistant | F32: Admin/Secertary | G32: 29657 | H32: Bachelor of Alsun | I32: Language and Translation | J32: Ain Shams | K32: 2004 | L32: 57292502 | M32: 28103120101985 | N32: 48339 | O32: N/A | P32: N/A | Q32: N/A | R32: 43534 | S32: 9 Nehad Sabry - Roxy | T32: Heliopolis | U32: Cairo | V32: 401 | W32: 012-21732578 | X32: Renewal for One Year | Y32: =Contracts!D64 -> 46090 | Z32: =DATEDIF(R32,TODAY(),"Y") -> 6 | AA32: =DATEDIF(R32,TODAY(),"Ym") -> 9 | AB32: 0 | AC32: 0 | AD32: Active
A33: 3-7 | B33: Admin | C33: Ahmed Samir Hassan EL Said | D33: احمد سمير حسن السيد | E33: Admin Assistant | F33: Litigation | G33: 30529 | H33: Bachelor of Alsun | I33: Language and Translation | J33: Ain Shams | K33: 2006 | L33: 61710995 | M33: 28308011600531 | N33: 47174 | O33: N/A | P33: N/A | Q33: N/A | R33: 44409 | S33: 7 Degla Al Estismary Buildings | T33: Maadi | U33: Cairo | V33: 437 | W33: 010-23131881 | X33: Renewal for One Year | Y33: =Contracts!D74 -> 46053 | Z33: =DATEDIF(R33,TODAY(),"Y") -> 4 | AA33: =DATEDIF(R33,TODAY(),"Ym") -> 5 | AB33: 10 | AC33: 0 | AD33: Resigned
A34: 3-8 | B34: Admin | C34: Eman Sobhy Shokry Khalil | D34: ايمان صبحى شكرى خليل | E34: Follow-Up Coordinator | F34: Admin/Secertary | G34: 23621 | H34: Bachelor of Social Work | I34: Sociology | J34: Helwan | K34: 1986 | L34: معاش | M34: 26409010103006 | N34: 11900 | O34: N/A | P34: N/A | Q34: N/A | R34: 42297 | S34: 9 Hay 11 - Megawra 2 | T34: Sheikh Zayed | U34: Giza | V34: 444 | W34: 012-22269214 | X34: Renewal for One Year | Y34: =Contracts!D82 -> 46314 | Z34: =DATEDIF(R34,TODAY(),"Y") -> 10 | AA34: =DATEDIF(R34,TODAY(),"Ym") -> 2 | AB34: 27 | AC34: 10 | AD34: Active
A35: 3-9 | B35: Admin | C35: Sherif Shokry Mohamed Abd El Hafez | D35: شريف شكرى محمد عبد الحافظ | E35: Librarian | F35: Admin/Secertary | G35: 26131 | H35: Bachelor of Laws | I35: Arabic | J35: Cairo | K35: 2010 | L35: 24767787 | M35: 27107170104235 | N35: 11034 | O35: N/A | P35: N/A | Q35: N/A | R35: 42397 | S35: 10 El Salam from Nasr Al Thawra St. | T35: Haram | U35: Giza | V35: 433 | W35: 012-71702020 | X35: Revewal for Six Month | Y35: =Contracts!D96 -> 46049 | Z35: =DATEDIF(R35,TODAY(),"Y") -> 9 | AA35: =DATEDIF(R35,TODAY(),"Ym") -> 11 | AB35: 20 | AC35: 5 | AD35: Active
A36: 3-10 | B36: Admin | C36: Mohamed Hassan Mohamed Kamel | D36: محمد حسن محمد كامل | E36: HR Generalist | F36: HR | G36: 32288 | H36: Bachlor of Commerce | I36: Accounting | J36: Helwan | K36: 2011 | L36: 20924633 | M36: 28805250100454 | N36: 11513 | O36: N/A | P36: N/A | Q36: N/A | R36: 45231 | S36: 48 El Shatr Al Sades - Alico Buildings | T36: Zahraa Al Maadi | U36: Cairo | V36: 413 | W36: 010-15337745 | X36: Renewal for One Year | Y36: =Contracts!D109 -> 46190 | Z36: =DATEDIF(R36,TODAY(),"Y") -> 2 | AA36: =DATEDIF(R36,TODAY(),"Ym") -> 2 | AB36: 16 | AC36: 3 | AD36: Active
A37: 3-11 | B37: Admin | C37: Samy Ibrahim Mohamed Youssef | D37: سامى ابراهيم محمد يوسف | E37: Supervisor of Paralegal Group | F37: Litigation | G37: 27884 | H37: High School | I37: Commercial | K37: 1996 | L37: 7813578 | M37: 27605042103439 | N37: 46120 | O37: N/A | P37: N/A | Q37: N/A | R37: 39827 | S37: Kafr Ghataty | T37: Haram | U37: Giza | V37: 432 | W37: 012-82349895 | X37: Revewal for Six Month | Y37: =Contracts!D116 -> 46022 | Z37: =DATEDIF(R37,TODAY(),"Y") -> 16 | AA37: =DATEDIF(R37,TODAY(),"Ym") -> 11 | AB37: 8 | AC37: 0 | AD37: Active
A38: 3-12 | B38: Admin | C38: Mahmoud Ali Mohmoud Hussein El Sayed | D38: محمود على محمود حسن السيد | E38: Paralegal | F38: Litigation | G38: 27401 | H38: Bachelor of Arts | I38: Geography | J38: Cairo | K38: 1996 | L38: 60446683 | M38: 27501078800292 | N38: 46241 | O38: N/A | P38: N/A | Q38: N/A | R38: 42186 | S38: 4 Bayoumi Moqbel | T38: Imbaba | U38: Giza | V38: 432 | W38: 012-06001011- 011-24455178 | X38: Renewal for One Year | Y38: =Contracts!D132 -> 46203 | Z38: =DATEDIF(R38,TODAY(),"Y") -> 10 | AA38: =DATEDIF(R38,TODAY(),"Ym") -> 6 | AB38: 15 | AC38: 4 | AD38: Active
A39: 3-13 | B39: Admin | C39: Amr Abd El Kerem Sakr Bayomy Sakr | D39: عمرو عبد الكريم صقر بيومى صقر | E39: Typist | F39: Litigation | G39: 28034 | H39: Bachelor of Arts | I39: Arabic | J39: Benha | K39: 2002 | L39: 24849461 | M39: 27610011407611 | N39: 11883 | O39: N/A | P39: N/A | Q39: N/A | R39: 41105 | S39: 26 Dagdag - Zaqaziq Road | T39: Banha | U39: Al Qalubyea | V39: 437 | W39: 011-14574400 - 012-80000647 | X39: Renewal for One Year | Y39: =Contracts!D146 -> 46217 | Z39: =DATEDIF(R39,TODAY(),"Y") -> 13 | AA39: =DATEDIF(R39,TODAY(),"Ym") -> 5 | AB39: 0 | AC39: 0 | AD39: Active
A40: 3-14 | B40: Admin | C40: Mokhtar Ahmed Mohamed El Magdaly | D40: مختار احمد محمد المجدلى | E40: Messenger | F40: Facilities | G40: 29321 | H40: Primary School | I40: - | J40: - | K40: 1990 | L40: 63299236 | M40: 28004102100191 | N40: 46761 | O40: N/A | P40: N/A | Q40: N/A | R40: 39583 | S40: Block 88 Masaken Sakyet Mekki | T40: Sakyet Mekki | U40: Giza | V40: 441 | W40: 012-70172555 | X40: Renewal for One Year | Y40: =Contracts!D162 -> 46340 | Z40: =DATEDIF(R40,TODAY(),"Y") -> 17 | AA40: =DATEDIF(R40,TODAY(),"Ym") -> 7 | AB40: 0 | AC40: 0 | AD40: Active
...

Sheet Contracts
A1: Name | C1: Contract Duration | D1: Comments
A2: From | B2: To
A3: 3-1 | B3: Doaa Abd El Dayem Ibrahim Nassar | D3: 46219
A5: 45855 | B5: 46219 | C5: Renewal for One Year
A6: 45490 | B6: 45854 | C6: Renewal for One Year
A7: 44759 | B7: 45489 | C7: Renewal for Two Year
A8: 44394 | B8: 44758 | C8: Renewal for One Year
A9: 44029 | B9: 44393 | C9: Renewal for One Year
A10: 43663 | B10: 44028 | C10: Renewal for One Year
A11: 43298 | B11: 43662 | C11: Renewal for One Year
A12: 42933 | B12: 43297 | C12: Renewal for One Year
A13: 42568 | B13: 42932 | C13: Renewal for One Year
A14: 42202 | B14: 42567 | C14: Renewal for One Year
A15: 41837 | B15: 42201 | C15: Renewal for One Year
A16: 41472 | B16: 41836 | C16: Renewal for One Year
A17: 41107 | B17: 41471 | C17: Hiring Contract
A18: 3-2 | B18: Khaled Mohamed Helmy Mohamed Yousry | D18: 46042
A20: 45678 | B20: 46042 | C20: Renewal for One Year
A21: 45312 | B21: 45677 | C21: Renewal for One Year
A22: 44947 | B22: 45311 | C22: Renewal for One Year
A23: 44763 | B23: 44946 | C23: Renewal for Six Month
A24: 44398 | B24: 44762 | C24: Renewal for One Year
A25: 44033 | B25: 44397 | C25: Renewal for One Year
A26: 43667 | B26: 44032 | C26: Renewal for One Year
A27: 43302 | B27: 43666 | C27: Renewal for One Year
A28: 43121 | B28: 43301 | C28: Renewal for Six Month
A29: 42756 | B29: 43120 | C29: Renewal for One Year
A30: 42390 | B30: 42755 | C30: Renewal for One Year
A31: 42025 | B31: 42389 | C31: Renewal for One Year
A32: 41660 | B32: 42024 | C32: Hiring Contract
A33: 3-3 | B33: Ahmed Mohamed Rezk Mohamed | D33: 46126
A36: 45762 | B36: 46127 | C36: Renewal for One Year
A37: 45397 | B37: 45761 | C37: Renewal for One Year
A38: 45031 | B38: 45396 | C38: Renewal for One Year
A39: 44666 | B39: 45030 | C39: Renewal for One Year
A40: 44484 | B40: 44665 | C40: Renewal for Six Month
A41: 44119 | B41: 44483 | C41: Renewal for One Year
A42: 43753 | B42: 44118 | C42: Renewal for One Year
A43: 43388 | B43: 43752 | C43: Renewal for One Year
A44: 43023 | B44: 43387 | C44: Hiring Contract
...

Sheet Personnel
A1: EmployeeID/Code | B1: Name | C1: Criminal Record | D1: Military Certificate | E1: ID Copy | F1: Education Certificate | G1: Birth Certificate | H1: Recommendation Letter | I1: Personal Photos | J1: Tax Card | K1: Association ID | L1: Form 6 | M1: Laptop / PC / Tablet | N1: كعب العمل | O1: تاريخ بداية التأمين | P1: Status
A2: 1-1 | B2: Dr. Hani Salah Mohamed Sarie Eldin | C2: X | D2: Copy | E2: √ | F2: Copy | G2: Copy | H2: X | I2: √ | J2: √ | K2: √ | L2: N/A | M2: Laptop | N2: N/A | O2: N/A | P2: Active
A3: 1-2 | B3: Ms. Amira Mohamed Ali Sherif | C3: X | D3: N/A | E3: √ | F3: Copy | G3: Copy | H3: X | I3: X | J3: √ | K3: √ | L3: N/A | M3: Laptop | N3: N/A | O3: N/A | P3: Active
A4: 2-1 | B4: Mohamed Abd El Aziz Abd El Hafez Mohamed | C4: X | D4: Copy | E4: √ | F4: Copy | G4: Copy | H4: X | I4: X | J4: √ | K4: √ | L4: N/A | M4: Laptop | N4: N/A | O4: N/A | P4: Active
A5: 2-2 | B5: Mohamed Hamdy Kamel Mostafa | C5: X | D5: Original | E5: √ | F5: Copy | G5: Original | H5: X | I5: √ | J5: √ | K5: √ | L5: N/A | M5: Laptop | N5: N/A | O5: N/A | P5: Active
A6: 2-3 | B6: Menna Allah Nabil Mohamed El Beltagy | C6: X | D6: N/A | E6: √ | F6: X | G6: X | H6: X | I6: X | J6: √ | K6: √ | L6: N/A | M6: Laptop | N6: N/A | O6: N/A | P6: Active
A7: 2-4 | B7: Ihab Hamdy Ibrahim Imam | C7: X | D7: Copy | E7: √ | F7: Original | G7: Original | H7: X | I7: X | J7: √ | K7: √ | L7: N/A | M7: Laptop | N7: N/A | O7: N/A | P7: Active
A8: 2-5 | B8: Noha Amr Mohamed Radwan | C8: √ | D8: N/A | E8: √ | F8: Original | G8: Copy | H8: X | I8: X | J8: √ | K8: √ | L8: N/A | M8: Laptop | N8: N/A | O8: N/A | P8: Active
A9: 2-6 | B9: Nagy Ramdan Amin Mohamed | C9: X | D9: Copy | E9: √ | F9: Copy | G9: Copy | H9: √ | I9: X | J9: √ | K9: √ | L9: N/A | M9: PC | N9: N/A | O9: N/A | P9: Active
A10: 2-7 | B10: Hany Ahmed Abd El Meged Mourad El Daly | C10: √ | D10: Copy | E10: √ | F10: Original | G10: Copy | H10: X | I10: X | J10: √ | K10: √ | L10: N/A | M10: PC | N10: N/A | O10: N/A | P10: Active
A11: 2-8 | B11: Ahmed Seif Eldin Abo Bakr Sarie Eldin | C11: √ | D11: X | E11: √ | F11: Copy | G11: Original | H11: √ | I11: √ | J11: X | K11: X | L11: N/A | M11: Laptop | N11: N/A | O11: 44197 | P11: Active
A12: 2-9 | B12: Ahmed Said Ahmed Mohamed Ali | C12: X | D12: X | E12: √ | F12: Copy | G12: Copy | H12: X | I12: √ | J12: √ | K12: √ | L12: N/A | M12: Laptop | N12: N/A | O12: N/A | P12: Active
A13: 2-10 | B13: Mahmoud Shabaan Mahmoud Hassan | C13: √ | D13: Copy | E13: √ | F13: Original | G13: Original | H13: X | I13: √ | J13: √ | K13: √ | L13: N/A | M13: PC | N13: N/A | O13: N/A | P13: Resigned
A14: 2-11 | B14: Omar Essam Hanafy Mahmoud | C14: √ | D14: Original | E14: √ | F14: Original | G14: Original | H14: X | I14: √ | J14: √ | K14: √ | L14: N/A | M14: Laptop | N14: N/A | O14: N/A | P14: Resigned
A15: 2-12 | B15: Mohamed Wally Abd El Hady Mohamed | C15: √ | D15: Original | E15: √ | F15: Original | G15: Original | H15: X | I15: √ | J15: X | K15: √ | L15: N/A | M15: Laptop | N15: N/A | O15: N/A | P15: Resigned
A16: 2-13 | B16: Yasmine Safwat Salah Eldin Ibrahim | C16: √ | D16: N/A | E16: √ | F16: Original | G16: Original | H16: √ | I16: √ | J16: X | K16: √ | L16: N/A | M16: Laptop | N16: N/A | O16: N/A | P16: Resigned
A17: 2-14 | B17: Habiba Mahmoud Samir Mahmoud Issa | C17: √ | D17: N/A | E17: √ | F17: Original | G17: Original | H17: X | I17: √ | J17: X | K17: √ | L17: N/A | M17: Laptop | N17: N/A | O17: N/A | P17: Active
A18: 2-15 | B18: Farah Abd Allah Mahmoud Al Nahas | C18: X | D18: N/A | E18: √ | F18: Copy | G18: Original | H18: X | I18: X | J18: √ | K18: √ | L18: N/A | M18: Laptop | N18: N/A | O18: N/A | P18: Resigned
A19: 2-16 | B19: Abdel Rahman Ahmed Abdel Aziz Hassan | C19: √ | D19: Original | E19: √ | F19: Original | G19: Original | H19: X | I19: √ | J19: √ | K19: √ | L19: N/A | M19: PC | N19: N/A | O19: N/A | P19: Active
A20: 2-17 | B20: Ahmed Abu El Abbas Mohamed Ahmed El Etreby | C20: √ | D20: Original | E20: √ | F20: Original | G20: Original | H20: X | I20: √ | J20: √ | K20: √ | L20: N/A | M20: Laptop | N20: N/A | O20: N/A | P20: Active
A21: 2-18 | B21: Laila Amin Mohamed Amin Tamoum | C21: √ | D21: N/A | E21: √ | F21: Original | G21: Original | H21: X | I21: √ | J21: √ | K21: √ | L21: N/A | M21: Laptop | N21: N/A | O21: N/A | P21: Active
A22: 2-19 | B22: Hussien Sherif Mohamed Monier Amer | C22: X | D22: Original | E22: √ | F22: Original | G22: Original | H22: X | I22: √ | J22: √ | K22: √ | L22: N/A | M22: Laptop | N22: N/A | O22: N/A | P22: Resigned
A23: 2-20 | B23: Kareem Ayman Mohamed Adel | C23: √ | D23: Copy | E23: √ | F23: Original | G23: Original | H23: √ | I23: √ | J23: √ | K23: √ | L23: N/A | M23: Laptop | N23: N/A | O23: N/A | P23: Active
... A25: 2-22 | B25: Amr Mohamed Abdel Haleem Abdo Sleem | C25: √ | D25: Original | E25: √ | F25: Original | G25: Original | H25: X | I25: √ | J25: X | K25: √ | L25: N/A | M25: PC | N25: N/A | O25: N/A | P25: Active
A26: 3-1 | B26: Ms. Doaa Abd El Dayem Ibrahim Nassar | C26: X | D26: N/A | E26: √ | F26: Original | G26: Original | H26: √ | I26: X | J26: N/A | K26: N/A | L26: √ | M26: Laptop | N26: X | O26: 41122 | P26: Active
A27: 3-2 | B27: Khaled Mohamed Helmy Mohamed Yousry Abd Rabo | C27: X | D27: Copy | E27: √ | F27: Original | G27: Copy | H27: X | I27: √ | J27: N/A | K27: √ | L27: X | M27: Laptop | N27: √ | O27: 41699 | P27: Active
A28: 3-3 | B28: Ahmed Mohamed Rezk Mohamed | C28: √ | D28: Original | E28: √ | F28: Original | G28: Original | H28: √ | I28: √ | J28: N/A | K28: √ | L28: √ | M28: PC | N28: √ | O28: 43009 | P28: Active
A29: 3-4 | B29: Irene Zaghloul Nazier Mohareb | C29: √ | D29: N/A | E29: √ | F29: Original | G29: Original | H29: √ | I29: √ | J29: N/A | K29: N/A | L29: √ | M29: PC | N29: √ | O29: 43831 | P29: Resigned
A30: 3-5 | B30: Nermine Essmat Mohamed Hegazy | C30: √ | D30: N/A | E30: √ | F30: Original | G30: Original | H30: √ | I30: √ | J30: N/A | K30: N/A | L30: √ | M30: PC | N30: √ | O30: 43252 | P30: Active
A31: 3-6 | B31: Marwa Sherif Abd El Hamid Salama | C31: √ | D31: N/A | E31: √ | F31: Original | G31: Original | H31: √ | I31: √ | J31: N/A | K31: N/A | L31: √ | M31: Tablet/Laptop | N31: √ | O31: 43556 | P31: Active
A32: 3-7 | B32: Ahmed Samir Hassan EL Said | C32: √ | D32: Original | E32: √ | F32: Original | G32: Original | H32: √ | I32: √ | J32: N/A | K32: N/A | L32: X | M32: PC | N32: √ | O32: 44409 | P32: Active
A33: 3-8 | B33: Eman Sobhy Shokry Khalil | C33: X | D33: N/A | E33: √ | F33: Original | G33: X | H33: √ | I33: X | J33: N/A | K33: N/A | L33: معاش مبكر | M33: Laptop | N33: X | O33: معاش مبكر | P33: Active
A34: 3-9 | B34: Sherif Shokry Mohamed Abd El Hafez | C34: √ | D34: Copy | E34: √ | F34: Copy | G34: Copy | H34: √ | I34: X | J34: N/A | K34: N/A | L34: √ | M34: PC | N34: √ | O34: 42401 | P34: Active
A35: 3-10 | B35: Mohamed Hassan Mohamed Kamel | C35: √ | D35: Original | E35: √ | F35: Original | G35: Original | H35: √ | I35: √ | J35: N/A | K35: N/A | L35: √ | M35: Laptop | N35: √ | O35: 45093 | P35: Active
A36: 3-11 | B36: Samy Ibrahim Mohamed Youssef | C36: X | D36: X | E36: √ | F36: Original | G36: Original | H36: √ | I36: X | J36: N/A | K36: N/A | L36: √ | M36: PC | N36: X | O36: 39814 | P36: Active
A37: 3-12 | B37: Mahmoud Ali Mohmoud Hussein El Sayed | C37: √ | D37: N/A | E37: √ | F37: Original | G37: Original | H37: √ | I37: X | J37: N/A | K37: N/A | L37: √ | M37: - | N37: √ | O37: 42222 | P37: Active
A38: 3-13 | B38: Amr Abd El Kerem Sakr Bayomy Sakr | C38: √ | D38: Original | E38: √ | F38: Original | G38: Original | H38: X | I38: X | J38: N/A | K38: N/A | L38: X | M38: Laptop | N38: X | O38: 43313 | P38: Active
A39: 3-15 | B39: Mokhtar Ahmed Mohamed El Magdaly | C39: √ | D39: Copy | E39: √ | F39: Copy | G39: X | H39: X | I39: X | J39: N/A | K39: N/A | L39: X | M39: - | N39: X | O39: 39814 | P39: Active
A40: 3-16 | B40: Tarek Mohamed Gomaa Abdallah | C40: X | D40: Copy | E40: √ | F40: Copy | G40: Copy | H40: X | I40: X | J40: N/A | K40: N/A | L40: X | M40: - | N40: X | O40: 40848 | P40: Active
A41: 3-17 | B41: Ahmed Mohamed Abdel Salam Mohamed | C41: √ | D41: Original | E41: √ | F41: Original | G41: Original | H41: X | I41: √ | J41: N/A | K41: N/A | L41: √ | M41: - | N41: √ | O41: 43252 | P41: Active
...

Sheet Resigned
A1: ID | B1: Classification | C1: Name | D1: Job Title | E1: Department/Division | F1: Date of Birth | G1: NationalID Number | H1: NationalID Valid till | I1: Bar Association Number | J1: Bar Association Degree (درجة القيد) | K1: Joining Date | L1: Date of Resignation
B2: Admin | C2: Alyaa Ibrahim Taha Ismail Nagd | D2: Administrative & HR Assistant | E2: HR | I2: N/A | J2: N/A | K2: 41821 | L2: 42461
B3: Lawyer | C3: Dr. Ahmed Abdallah Mohamed Ali | D3: Partner | F3: 27281 | G3: 27409092102758 | H3: 43837 | L3: 42614
B4: Lawyer | C4: Amir Adel Aziz Gerges Matar | D4: Associate | G4: 28501230101617 | K4: 42309 | L4: 42675
B5: Admin | C5: Nermine El-Sisi | D5: Admin Assistant | E5: Admin/Secertary | I5: N/A | J5: N/A | L5: 42675
B6: Admin | C6: Abd El Nasser Osman Hassan Ibrahim | D6: Financial Advisor | E6: Accounting | F6: 23565 | G6: 26407072101392 | H6: 45263 | I6: N/A | J6: N/A | K6: 39448 | L6: 42742
B7: Lawyer | C7: Amr Abd El Rehim | D7: Associate | K7: 42239 | L7: 42804
B8: Admin | C8: Mary Magdy Thabet Said | D8: Admin Assistant | E8: Admin/Secertary | F8: 31358 | G8: 28511070100304 | H8: 45144 | I8: N/A | J8: N/A | K8: 42562 | L8: 42831
B9: Lawyer | C9: Sherif Abo El Makarem Saleh Soliman | D9: Associate Corporate Procedures | F9: 30922 | G9: 28408282103413 | H9: 23/8/2023 | K9: 40125 | L9: 42950
B10: Admin | C10: Safaa Ahmed Mohamed Atallah | D10: Admin Assistant | E10: Admin/Secertary | F10: 26007 | G10: 27103150101668 | H10: 45349 | I10: N/A | J10: N/A | K10: 41251 | L10: 42956
B11: Admin | C11: Dalia Ahmed Mourad Gamal El Din | D11: Accountant | E11: Accounting | F11: 31921 | G11: 28705242100041 | H11: 44593 | I11: N/A | J11: N/A | K11: 41642 | L11: 42981
B12: Lawyer | C12: Lina Mahmoud Radwan Kenawy | D12: Associate | F12: 32279 | G12: 28805160103942 | H12: 13/4/2022 | K12: 41875 | L12: 43009
B13: Lawyer | C13: Dr. Khaled Attia | D13: Partner | K13: 40179 | L13: 43100
B14: Admin | C14: Sherine Samir Fayek Naguib | D14: Executive Assistant / Managing Partner | E14: Admin/Secertary | F14: 24712 | G14: 26708280100804 | H14: 45160 | I14: N/A | J14: N/A | K14: 42418 | L14: 43131
B15: Admin | C15: Nourane Ahmed Fahmy Hussein Fahmy Ahmed | D15: Admin Assistant | E15: Admin/Secertary | F15: 32325 | G15: 28807012110789 | H15: 43903 | I15: N/A | J15: N/A | K15: 42824 | L15: 43226
B16: Admin | C16: Ahmed El Sayed Faheem Ali | D16: Office Boy | E16: Facilities | F16: 33366 | G16: 29105081401115 | H16: 45298 | I16: N/A | J16: N/A | K16: 42544 | L16: 43251
B17: Admin | C17: Aliaa Mohamed Kassem Maamoun | D17: PR and Marketing Coordinator | E17: Marketing | F17: 33468 | G17: 29108182103106 | H17: 44573 | I17: N/A | J17: N/A | K17: 42983 | L17: 43258
B18: Admin | C18: Khaled Samy Sayed Mostafa | D18: Dr. Hani's Driver | E18: Facilities | F18: 23556 | G18: 26406280100174 | H18: 43314 | I18: N/A | J18: N/A | K18: 40543 | L18: 43272
B19: Admin | C19: Layla Mohamed Ihab Mostafa Abd El Latef | D19: Executive Assistant | E19: Admin/Secertary | F19: 32899 | G19: 29001262101709 | H19: 45361 | I19: N/A | J19: N/A | K19: 43177 | L19: 43527
B20: Lawyer | C20: Mohamed Magdy Sayed Ahmed Ramdan El Gharably | D20: Litigation Senior Associate | F20: 31623 | G20: 28607300201196 | H20: 45621 | J20: استئناف | K20: 40848 | L20: 43534
B21: Lawyer | C21: Wessam Ahmed Saleh Ali El Sayed | D21: Associate | F21: 32336 | G21: 28812072102509 | H21: 44984 | J21: غير مقيد | K21: 42370 | L21: 43593
B22: Lawyer | C22: Hania Badr Eldin Abo ElOyoun Ahmed Fouad | D22: Associate | F22: 34115 | G22: 29305260201128 | H22: 45641 | J22: ابتدائي | K22: 43102 | L22: 43608
B23: Lawyer | C23: Abdallah Amr Abd El Aziz Mohamed Hafez | D23: Junior Associate | F23: 34680 | G23: 29412120102597 | H23: 46050 | J23: غير مقيد | K23: 43482 | L23: 43643
B24: Admin | C24: Zeina Ahmed Abd El Monem Ahmed Attia | D24: Senior Executive assistant | E24: Admin/Secertary | F24: 31201 | G24: 28506032103509 | H24: 45604 | I24: N/A | J24: N/A | K24: 42217 | L24: 43683
B25: Lawyer | C25: Aly Mostafa Aly Hassan Salem | D25: Associate | F25: 32518 | G25: 28910011337475 | H25: 45461 | J25: ابتدائى | K25: 43135 | L25: 43727
B26: Admin | C26: Gihan Kamal Nassif Salib | D26: Executive Assistant | E26: Admin/Secertary | F26: 25052 | G26: 26808020200605 | H26: 45110 | I26: N/A | J26: N/A | K26: 43753 | L26: 43811
B27: Admin | C27: Heidi Magdy Maher Wahba felobus | D27: Receptionist & Office Secretary | E27: Admin/Secertary | F27: 33264 | G27: 29101262103242 | H27: 45634 | I27: N/A | J27: N/A | K27: 42738 | L27: 43921
B28: Lawyer | C28: Mountasser Hesham Mohamed Abdullah Ibrahim El Masry | D28: Associate | F28: 33248 | G28: 29101100201119 | H28: 46322 | J28: ابتدائى | K28: 43625 | L28: 44077
B29: Lawyer | C29: Momen Abdallah Mohamed Ahmed Selim | D29: Associate | F29: 33813 | G29: 29207282102253 | H29: 44825 | J29: ابتدائي | K29: 42644 | L29: 44180
B30: Lawyer | C30: Mostafa Khaled Mohamed Khair Eldin Nassar | D30: Senior Associate | F30: 32406 | G30: 28809202106071 | H30: 44379 | J30: ابتدائي | K30: 42983 | L30: 44195
B31: Admin | C31: Rezk Fathy Rowished Mohamed | D31: Dr. Hani's Driver | E31: Facilities | F31: 30569 | G31: 28309102102432 | H31: 45787 | I31: N/A | J31: N/A | K31: 43446 | L31: 44227
B32: Lawyer | C32: Nermine Hani Mahmoud Abd El Aal | D32: Junior Associate | F32: 35658 | G32: 29708162100761 | H32: 44117 | I32: 672465 | J32: جدول عام | K32: 43983 | L32: 44423
B33: Admin | C33: Khaled Kamal Fawzy Amer El Sisi | D33: Admin Assistant | E33: Admin/Secertary | F33: 29432 | G33: 28007300100112 | H33: 45701 | I33: N/A | J33: N/A | K33: 41939 | L33: 44439
B34: Lawyer | C34: Dr. Ahmed Abdallah Mohamed Ali | D34: Partner | F34: 27281 | G34: 27409092102758 | H34: 46212 | J34: نقض | K34: 43661 | L34: 44439
B35: Lawyer | C35: Mohamed Tarek Mohamed Ahmed ElKhateb | D35: Junior Associate | F35: 35037 | G35: 29512042100498 | H35: 46321 | I35: 636830 | J35: جدول عام | L35: 44501
B36: Lawyer | C36: Mohamed Essam Ahmed Fouad Abo El Naga | D36: Associate | F36: 31532 | G36: 28604300102652 | H36: 44524 | I36: 509550 | J36: ابتدائى | K36: 43619 | L36: 44538
B37: Lawyer | C37: Abdallah Amr Abd El Aziz Mohamed Hafez | D37: Junior Associate | F37: 34680 | G37: 29412120102597 | H37: 46050 | I37: 651901 | J37: جدول عام | K37: 44087 | L37: 44538
B38: Lawyer | C38: Omar Ahmed Mohamed Fouad Shady | D38: Associate | F38: 33180 | G38: 29011030102275 | H38: 46459 | I38: 595593 | J38: ابتدائي | K38: 43716 | L38: 44551
B39: Admin | C39: Eslam Khaled Mostafa Mohamed Abdallah | D39: Receptionist | E39: Admin/Secertary | F39: 34409 | G39: 29403168800351 | H39: 46822 | I39: N/A | J39: N/A | K39: 43916 | L39: 44560
B40: Lawyer | C40: Ahmed Nabil Mohamed Gamal El Din Farahat | D40: Partner | F40: 31120 | G40: 28503142103033 | H40: 46106 | I40: 620384 | J40: ابتدائي | K40: 41161 | L40: 44658
...

Sheet Employee Card
A1: Employee Card
A2: ID No. | B2: 2-19 | F2: Classification | I2: =VLOOKUP(B2,AllOffice!A1:AD1005,2,) -> Lawyer
A4: Basic Info
A5: Name | C5: =VLOOKUP(B2,AllOffice!A1:AD1005,3,) -> Hussien Sherif Mohamed Monier Amer
A6: Joining Date | C6: =VLOOKUP(B2,AllOffice!A1:AD1005,17,) -> -
A7: Job Title | C7: =VLOOKUP(B2,AllOffice!A1:AD1005,4,) -> حسين شريف محمد منير عامر
A8: Department | C8: =VLOOKUP(B2,AllOffice!A1:AD1005,5,) -> Associate
A9: Date of Birth | C9: =VLOOKUP(B2,AllOffice!A1:AD1005,6,) -> Banking & Procedures
A10: Mobile Number | C10: =VLOOKUP(B2,AllOffice!A1:AD1005,22,) -> 406
A12: Education
A13: Certificate Type | C13: =VLOOKUP(B2,AllOffice!A1:AD1005,7,) -> 35383
A14: Section | C14: =VLOOKUP(B2,AllOffice!A1:AD1005,8,) -> Master of Laws
A15: University | C15: =VLOOKUP(B2,AllOffice!A1:AD1005,9,) -> Professional Legal Practice
A16: Graduation Year | C16: =VLOOKUP(B2,AllOffice!A1:AD1005,10,) -> University of Law
A18: IDs
A19: National ID | C19: =VLOOKUP(B2,AllOffice!A1:AD1005,12,) -> -
A20: Bar Association No. | C20: =VLOOKUP(B2,AllOffice!A1:AD1005,14,) -> 47469
A21: درجة القيد | C21: =VLOOKUP(B2,AllOffice!A1:AD1005,15,) -> 710391
A22: Tax Card No. | C22: =VLOOKUP(B2,AllOffice!A1:AD1005,16,) -> جدول عام
A23: Social Insurance | C23: =VLOOKUP(B2,AllOffice!A1:AD1005,11,) -> 2021
A25: Address
A26: Address Details | C26: =VLOOKUP(B2,AllOffice!A1:AD1005,18,) -> 45397
A27: Region | City | C27: =VLOOKUP(B2,AllOffice!A1:AD1005,19,) -> Villa 26 Telal Al Guziera
A28: Governorate | C28: =VLOOKUP(B2,AllOffice!A1:AD1005,20,) -> Sheikh Zayed
A30: Contract
A31: Duration | C31: =VLOOKUP(B2,AllOffice!A1:AD1005,23,) -> 010-00969141
A32: Renewal Date | C32: =VLOOKUP(B2,AllOffice!A1:AD1005,24,) -> Service Agreement
A34: Salary
